Workbook
Name _ftn1: #REF!
Name _ftn1: #REF!
Name _ftn1: #REF!
Name _ftn1: #REF!
Name _ftn1: #REF!
Name _ftn1: #REF!
Name book: #REF!
Name book: #REF!
Name book: #REF!
Name book: #REF!
Name book: #REF!
Name サービス業: #REF!
Name サービス業: #REF!
Name サービス業: #REF!
Name サービス業: #REF!
Name サービス業: 申請者2!$P$5:$P$33
Name 卸売業: #REF!
Name 卸売業: #REF!
Name 卸売業: #REF!
Name 卸売業: #REF!
Name 卸売業: 申請者2!$O$5:$O$11
Name 小売業: #REF!
Name 小売業: #REF!
Name 小売業: #REF!
Name 小売業: #REF!
Name 小売業: 申請者2!$Q$5:$Q$15
Name 製造業その他: #REF!
Name 製造業その他: #REF!
Name 製造業その他: #REF!
Name 製造業その他: #REF!
Name 製造業その他: #REF!
Name 製造業その他: 申請者2!$N$5:$N$65
Name 要件確認: #REF!
Name 要件確認: #REF!
Name 要件確認: #REF!
Name 要件確認: #REF!
Name 要件確認: #REF!

Sheet 表紙
C1: 様式第１号(第７条関係)
C3: 公益財団法人 東京都中小企業振興公社
D4: 理 事 長 殿
G7: 事業形態 | J7: 法人
G8: 申請者区分 | J8: A: 中小企業者(賃上げなし)
G9: 本店所在地 | J9: 東京都品川区荏原4-3-18 丸福ビル2階
G11: 名 称 | J11: 株式会社プルスウルトラ
G13: 代表者 | J13: （役職） | L13: 代表取締役
J14: （氏名） | L14: 木下大輔
A18: 令和７年度 事業環境変化に対応した経営基盤強化事業 (一般コース) 申請書
B21: 下記のとおり助成事業を実施したいので、別紙の書類を添えて、助成金の交付を申請します。
A24: 記
B26: １．申請テーマ
C28: （２０文字程度で自由記載）
B32: ２．助成金交付申請額
C34: =IF(資金!AJ19=0,"",資金!AJ19) -> 7011000
F35: 円
B38: ３．事業終了予定日
N41: ver.3_251225

Sheet 申請者1
A2: Ⅰ 申請者概要
A4: １．申請者の概要
A5: 申請区分 （個人事業主、法人） | F5: =IF(OR(表紙!J7="",表紙!J7="(選択)"),"",表紙!J7) -> 法人
A7: ＜個人事業主＞
A8: フリガナ | F8: 屋号 | H8: =IF(NOT(表紙!J7="個人事業主"),"",IF(表紙!J11="","",表紙!J11))
A9: 申請者氏名 | B9: =IF(NOT(表紙!J7="個人事業主"),"",IF(表紙!L14="","",表紙!L14)) | F9: 生年月日 | H9: 年 月 日
F10: TEL
A11: 郵便番号 | B11: 〒 － | F11: E-mail
A12: 本店所在地 | B12: =IF(NOT(表紙!J7="個人事業主"),"",IF(表紙!J9="","",表紙!J9))
A14: ＜法人＞
A15: フリガナ | B15: カブシキガイシャプルスウルトラ
A16: 法人名 | B16: =IF(NOT(表紙!J7="法人"),"",IF(表紙!J11="","",表紙!J11)) -> 株式会社プルスウルトラ
A17: 本店所在地 | B17: 郵便番号 | C17: 〒142－0063
B18: 住所 | C18: =IF(NOT(表紙!J7="法人"),"",IF(表紙!J9="","",表紙!J9)) -> 東京都品川区荏原4-3-18 丸福ビル2階
A19: 法人代表者 | B19: 役職 | C19: =IF(NOT(表紙!J7="法人"),"",IF(表紙!L13="","",表紙!L13)) -> 代表取締役 | F19: 生年月日 | G19: 29865
B20: フリガナ | C20: キノシタダイスケ | F20: TEL | G20: 090-1805-0178
B21: 氏名 | C21: =IF(NOT(表紙!J7="法人"),"",IF(表紙!L14="","",表紙!L14)) -> 木下大輔 | F21: E-mail | G21: D.kinoshita@pltra.co.jp
A22: 事業担当者 ※店舗従業者が代表と異なる場合のみ | B22: フリガナ | F22: 生年月日 | G22: 年 月 日
B23: 氏名 | F23: 部署・役職
F24: 雇用形態
A25: 連絡担当者 ※代表者と 異なる場合のみ | B25: フリガナ | F25: 部署・役職
B26: 氏名 | F26: TEL
F27: E-mail
A28: 都内登記 所在地 ※本店所在地が都外の場合のみ | B28: 郵便番号 | C28: 〒 －
B29: 住所

Sheet 申請者2
A1: 事業開始 | C1: 創業 （和暦） | D1: 42648 | H1: 資本金 | I1: 2000000 | L1: 円
C2: 法人設立 （和暦） | D2: 42648
A3: 役員数 | C3: 2 | F3: 人（監査役を含む） | H3: 従業員数 | I3: 0 | J3: 人（うち正社員 | L3: 人）
A4: 主たる業種 ※売上高構成比が最も高い事業の業種をご選択ください。 | C4: 大分類 | D4: サービス業 | F4: 中分類 | G4: 73広告業 | I4: 年間売上高 | J4: 18640000 | L4: 円 | M4: 選択してください | N4: 製造業その他 | O4: 卸売業 | P4: サービス業 | Q4: 小売業
A5: 現在の事業概要 ※業種、業態、特徴等を出来るだけ詳細にご記入ください。 | C5: 広告制作を主軸とする。2016年設立以来、企業および政治家等の広報・広告デザイン事業を展開。グラフィックデザイン業務を中心に、企業広報誌の取材・編集および情報発信支援を得意とする。コロナ禍では取材活動が制限され、多くの企業が紙媒体から動画へ広告媒体を転換したことから、写真・グラフィックデザインの経験を活かし動画制作事業へ展開。しかし企業広報・広告事業は現在も回復に至っておらず、新たな収益源確保のため、代表者の写真技術を活かした事業展開を模索。2022年よりファインアート写真制作（プラチナパラジウムプリント）技術の習得を開始し、2024年より作家活動を本格化。国内主要写真賞受賞（JPA優秀賞、JPS奨励賞等）、京都国際写真祭ピックアップアーティスト選出、ディスカバリーアワードファイナリスト選出等の実績を重ね、専門誌からの執筆依頼やワークショップ開催要請が増加。これらを契機に、古典写真技法の教育・制作支援事業への展開可能性を見出した。 | N5: 選択してください | O5: 選択してください | P5: 選択してください | Q5: 選択してください
A6: 主要取引先（上位3先） | I6: 直近年間取引高 | N6: 01農業 | O6: 50各種商品卸売業 | P6: 38放送業 | Q6: 34ガス業
A7: 1 | B7: 川崎市議会議員飯田満 | I7: 2930000 | L7: 円 | N7: 02林業 | O7: 51繊維・衣服等卸売業 | P7: 39情報サービス業 ※ソフトウェア業、情報処理・提供サービス業除く | Q7: 35熱供給業
A8: 2 | B8: 株式会社成建 | I8: 2650000 | L8: 円 | N8: 03漁業（水産養殖業を除く） | O8: 52飲食料品卸売業 | P8: 41映像・音声・文字情報制作業 ※新聞業、出版業を除く | Q8: 56各種商品小売業
A9: 3 | B9: 日本維新の会 | I9: 2350000 | L9: 円 | N9: 04水産養殖業 | O9: 53建築材料，鉱物・金属材料等卸売業 | P9: 48運輸に附帯するサービス業 | Q9: 57織物・衣服・身の回り品小売業
A10: その他の取引先 | I10: 10710000 | L10: 円 | N10: 05鉱業，採石業，砂利採取業 | O10: 54機械器具卸売業 | P10: 69不動産賃貸業・管理業 ※駐車場業のみ | Q10: 58飲食料品小売業
A11: 合計 | I11: =SUM(I7:K10) -> 18640000 | L11: 円 | N11: 06総合工事業 | O11: 55その他の卸売業 | P11: 70物品賃貸業 | Q11: 59機械器具小売業
N12: 07職別工事業(設備工事業を除く) | P12: 72専門サービス業（他に分類されないもの） | Q12: 60その他の小売業
A13: ２．事業の実施場所 | N13: 08設備工事業 | P13: 73広告業 | Q13: 61無店舗小売業
A14: 本助成事業を実施し、公社が検査時に、購入品や助成事業における成果物等、支払いに係る経理関係書類を確認できる場所を記入してください。原則、東京都内の自社の本社・事業所・工場等（借り上げ可）に限ります。 | N14: 09食料品製造業 | P14: 74技術サービス業（他に分類されないもの） | Q14: 76飲食店
A15: 名称 | C15: MT-O中野新橋 | G15: TEL | I15: 090-1805-0178 | N15: 10飲料・たばこ・飼料製造業 | P15: 75宿泊業 | Q15: 77持ち帰り・配達飲食サービス業
A16: 所在地 | C16: 〒 － | E16: 東京都 | G16: 中野区本町5-6-6 | N16: 11繊維工業 | P16: 78洗濯・理容・美容・浴場業
A17: 最寄駅 | C17: 線路名 | F17: 線 | G17: 駅名 | K17: 駅 | N17: 12木材・木製品製造業（家具を除く） | P17: 79その他の生活関連サービス業
N18: 13家具・装備品製造業 | P18: 80娯楽業
N19: 14パルプ・紙・紙加工品製造業 | P19: 81学校教育
A20: ３．役員・株主名簿＜法人＞ | N20: 15印刷・同関連業 | P20: 82その他の教育，学習支援業
A21: 履歴事項全部証明書に記入されている全役員及び持株比率が７０％を超えるまでの全ての株主を持ち株比率が多い順に記入してください。「役員」「株主」欄はそれぞれ該当するものに「〇」を、「役職等」欄には役員の「役職」を、役員以外の方は「申請者との関係又は職業」を記載してください。 ※合同会社の方は「株主」「持ち株数」「持ち株比率」については記入不要です。 | N21: 16化学工業 | P21: 83医療業
N22: 17石油製品・石炭製品製造業 | P22: 84保健衛生
N23: 18プラスチック製品製造業（別掲を除く） | P23: 85社会保険・社会福祉・介護事業
N24: 19ゴム製品製造業 | P24: 87協同組合（他に分類されないもの）
A25: NO. | B25: 氏名 | E25: 役員 | F25: 株主 | G25: 役職等 | J25: 持ち株数 | K25: 持ち株比率 | N25: 20なめし革・同製品・毛皮製造業 | P25: 88廃棄物処理業
A26: 1 | B26: 木下大輔 | E26: ○ | F26: ○ | G26: 代表取締役 | J26: 200 | K26: 1 | N26: 21窯業・土石製品製造業 | P26: 89自動車整備業
A27: 2 | B27: 木下真理 | E27: ○ | G27: 取締役 | N27: 22鉄鋼業 | P27: 90機械等修理業（別掲を除く）
A28: 3 | N28: 23非鉄金属製造業 | P28: 91職業紹介・労働者派遣業
A29: 4 | N29: 24金属製品製造業 | P29: 92その他の事業サービス業
A30: 5 | N30: 25はん用機械器具製造業 | P30: 93政治・経済・文化団体
A31: － | B31: その他の株主 | N31: 26生産用機械器具製造業 | P31: 94宗教
A32: 合計 | J32: =SUM(J26:J31) -> 200 | K32: =SUM(K26:L31) -> 1 | N32: 27業務用機械器具製造業 | P32: 95その他のサービス業
A33: 役員・株主名簿が「履歴事項全部証明書」「確定申告書別表2」と異なる場合の理由について | N33: 28電子部品・デバイス・電子回路製造業 | P33: 96外国公務
N34: 29電気機械器具製造業
N35: 30情報通信機械器具製造業
N36: 31輸送用機械器具製造業
N37: 32その他の製造業
N38: 33電気業
N39: 34ガス業
N40: 35熱供給業
...

Sheet 申請者3
B1: ４．補助金・助成金申請状況 | Z1: (選択)
B2: （１）過去5年間に国・都・公社等から補助金・助成金の交付を受けましたか。 | L2: はい | Z2: 2023年1月期
B3: （２）現在実施中又は申請中（予定を含む）の補助金・助成金はありますか。 | L3: いいえ | Z3: 2023年2月期
Z4: 2023年3月期
B5: （１）、(２)のいずれかもしくは両方が「はい」の場合、直近のものから順に記入してください。 | Z5: 2023年4月期
B6: 年度 | D6: 申請先 | G6: 補助・助成事業名 | J6: 助成金額 | L6: 本申請との経費の重複 | M6: 本申請との内容の重複 | N6: 状態 | Z6: 2023年5月期
B7: 令和２年度 | D7: 全国商工会連合会 | G7: 小規模事業者持続化補助金 | J7: 1000 | K7: 千円 | L7: 無 | M7: 無 | N7: 交付済 | Z7: 2023年6月期
K8: 千円 | L8: (選択) | M8: (選択) | N8: (選択) | Z8: 2023年7月期
K9: 千円 | L9: (選択) | M9: (選択) | N9: (選択) | Z9: 2023年8月期
K10: 千円 | L10: (選択) | M10: (選択) | N10: (選択) | Z10: 2023年9月期
B11: ※５つ以上ある場合には、特に本申請に関連のあるもの４つを記載してください。 | Z11: 2023年10月期
Z12: 2023年11月期
B13: (２)が「はい」かつ、本申請との経費または内容の重複が「有」のものについて、重複助成防止の観点から必ず下表を作成してください。 | Z13: 2023年12月期
B14: 本申請と、経費または内容の重複が「有」の補助金・助成金 | Z14: 2024年1月期
B15: 補助・助成事業名 | Z15: 2024年2月期
B16: テーマ名 | Z16: 2024年3月期
B17: 申請状況 | C17: (選択) | F17: (選択) | I17: (選択) | L17: (選択) | Z17: 2024年4月期
B18: 事業内容 | Z18: 2024年5月期
B19: 対象期間 | Z19: 2024年6月期
B20: 本助成事業との相違点 | Z20: 2024年7月期
B21: 対象経費 | Z21: 2024年8月期
B22: 経費支出先 | Z22: 2024年9月期
B23: 成果物 | Z23: 2024年10月期
Z24: 2024年11月期
Z25: 2024年12月期
B26: ５．決算状況（要件確認） | Z26: 2025年1月期
B27: （１）要件確認 | Z27: 2025年2月期
B28: 申請要件 | C28: ａ | D28: ａ．直近決算期の売上高が「2023年決算期以降のいずれかの決算期」と比較して減少している | Z28: 2025年3月期
Z29: 2025年4月期
D30: ｂ．直近決算期において損失を計上している | Z30: 2025年5月期
Z31: 2025年6月期
D32: ｃ．米国関税措置による影響により、次期決算期の売上高が、直近決算期の売上高と比較して減少することを見込んでいる | Z32: 2025年7月期
B33: （２）業績確認 ※（１）で選択した申請要件（ａまたはｂまたはｃ）について記入 | Z33: 2025年8月期
B34: 該当要件 | C34: 決算期 | E34: (具体的な時期) | G34: 入力項目 | L34: 金額 | Z34: 2025年9月期
B35: 要件ａ | C35: 直近期 | E35: 2025年9月期 | G35: 売上高 | L35: 16558000 | N35: 円 | Z35: 2025年10月期
G36: (選択) | L36: -3756000 | N36: 円 | Z36: 2025年11月期
C37: 比較対象期 | E37: 2023年9月期 | G37: 売上高 | L37: 33300000 | N37: 円 | Z37: 2025年12月期
G38: (選択) | L38: 511000 | N38: 円 | Z38: 2026年1月期
B39: 要件ｂ | C39: 直近期 | E39: (選択) | G39: 売上高 | N39: 円 | Z39: 2026年2月期
G40: (選択) | N40: 円 | Z40: 2026年3月期
...

Sheet 計画1
B2: Ⅱ 事業計画
B3: １．事業計画
B4: （１）自社を取り巻く環境に係るSWOT分析
B5: 内部環境 | C5: 強み（活かすべき自社内の強み） | L5: 弱み（障害となり克服すべき自社内の弱み）
C6: 専門性: プラチナプリント作家としての実績、国内主要写真展で受賞経験 / 業界トップとの連携: 猪股良文氏(元アトリエ・シャテーニュ)、久保元幸氏(ザ プリンツ)との業務提携。さらに東京工芸大学名誉教授 内藤明氏、日本写真芸術学会 高橋則英会長および東京工芸大学芸術学部写真学科 大和田良准教授との連携 / 事業基盤: 2016年から広告制作・商業写真撮影事業を展開 / 保持する希少設備: デジタルネガ出力用特殊プリンター(日本初)や写真専用UV露光機 | L6: 作家としての認知度不足: 作家活動3年、市場での認知拡大が必要 / 用途に合った物件探しの難しさ: 水を多用する設備条件が必要 / 初期投資: 写真専用暗室制作の実績がなく、外部専門家への委託が必要 / 専門人材の育成: 専門性が高く人材育成に時間を要する。熟練技術者の高齢化により技術習得の時間が限られている
B11: 外部環境 | C11: 機会（市場での競合優位性などプラス要素） | L11: 脅威（市場縮小や競合激化などマイナス要素）
C12: 世界的アナログ回帰: 写真アート市場年率6%成長、ファインアートプリント市場年率6.7%成長 / 日本市場の空白: 古典技法を体系的に学べる常設施設が不在 / 若年層の関心: Instagram #filmisnotdead 3,000万件超、Z世代の物質性回帰 / 古典技法作品の収集強化: 世界的な潮流として美術館での収集が拡大 / 海外との格差: 米国・欧州に総合型ラボ多数、日本は不足 / 教育機関の限界: 大学・専門学校では古典技法の紹介にとどまり、詳細な技術習得の場が不在 | L12: 材料費高騰リスク: プラチナ等貴金属価格変動により材料費が不安定。為替変動の影響も大きく、海外からの薬品・用紙調達コストが予測困難 / 技術継承断絶: 熟練技術者の高齢化が進み、引退により技術・ノウハウの継承機会が失われる / 競合参入: 成功モデル確立後、類似施設による模倣参入の可能性。ただし初期投資の大きさと専門技術者確保の困難さが参入障壁となる
B17: 分析結果の総括
B18: SO戦略: 業界トップ技術者・代表者の専門性×世界的潮流で日本市場のファーストムーバー優位性確立、トップ技術者連携×空白市場で唯一のソリューション化 ST戦略: 材料開発研究で材料費リスク対応、技術標準化で継承確実化 WO戦略: 世界的潮流を広報材料に作家認知度向上、市場空白により初期投資回収可能、若年層関心を活かし人材育成 WT戦略: 設備条件とコスト最適化で物件探し対応、初期投資の大きさが参入障壁 【総括】業界トップ技術者との連携と代表者の専門性を活かし、世界的なアナログ回帰と日本市場の空白を捉え、ファーストムーバー優位性を確立。材料開発・技術標準化でリスク対応し、初期投資の大きさが参入障壁となり競合優位性を維持。
B23: （２）取組の基となる「既存事業」
B24: 取組の基となる 既存事業の内容 | F24: ①メイン事業(2016年〜): 広告制作、商業写真撮影・取材 ②コロナ後拡張(2020年〜): 動画制作 ③派生事業(2025年8月〜): プラチナプリントワークショップ講師 【事業拡張の契機】代表者が2022年よりファインアート写真制作(プラチナプリント)技術を習得し、2024年より作家活動を本格化。専門誌からの執筆依頼(カメラホリック、フジヤカメラ等)、ワークショップ開催提案が複数寄せられ、SNS・個展を通じて「技術を学びたい」という問い合わせが継続的に届き、教育事業への展開可能性を確信。 【代表者実績】プラチナプリント開始2022年、初個展2024年4月、受賞6件(JPA優秀賞、JPS奨励賞、KG+ Discovery Awardファイナリスト等)、個展4回
B32: 上記の既存事業を 選んだ理由 （SWOT分析との関連性など） | F32: 技術的連続性: 商業写真のデジタル画像処理技術はデジタルネガ制作の基盤となり、色調・階調管理の経験は品質管理に直接活用できる。 顧客基盤の連続性: 作家活動で接点を持ったプロフェッショナル作家はプリント受注・コミュニティの中核となり、そのムーブメントによりハイアマチュアや写真学生が新規顧客層となる。 事業運営ノウハウの連続性: SNS発信は新事業マーケティングに転用でき、品質管理手法はワークショップ・受注制作の品質保証に直結する。 代表者の専門性の深化: 10年以上の写真実務経験とプラチナプリント作家3年間の実績が、新事業の実現可能性を担保する。

Sheet 計画2
B3: （３）取組内容
B4: 深化・発展の 取組内容 | F4: 【本取組の位置づけ】既存事業(広告制作・写真事業)の技術とネットワークを基盤に、古典写真技法の総合施設「Alternative Process Lab」を開設し、教育・制作支援事業へ発展させる。 【6つの事業柱】 ①ワークショップ事業: 12種類の古典写真技法(サイアノタイプ、プラチナプリント、湿板写真等)、デジタルネガ制作講座、海外作家招聘マスタークラス ②レンタル暗室事業: 日本初のオルタナティブ専用レンタル暗室。継続制作を支援する会員制システム ③プリント制作受注サービス: プラチナ・パラジウム、銀塩、湿板写真の受注制作。対象はプロ写真家、ギャラリー、コレクター、美術館 ④デジタルネガ出力サービス: 日本初の古典技法専用デジタルネガ出力。全国対応の通販体制 ⑤コミュニティ事業: 月例講評会、著名作家レクチャー、ギャラリー連携展示、国際ラボ交流 ⑥産学連携・研究事業: 大学(東京工芸大学・日大藝術学部等)との教育カリキュラム開発および写真専門機関(日本カメラ博物館等)との共同研究
B11: 上記の取組が「既存事業に基づく取組」と言える理由 | F11: 技術的連続性: 既存事業のデジタル画像処理技術はデジタルネガ制作の基盤となり、色調・階調管理の経験は品質管理に直接活用できる。 顧客基盤の連続性: 代表者の作家活動を通じて接点を持ったプロフェッショナル作家や写真愛好家が、プリント受注・コミュニティの中核顧客となる。また既存事業の広告制作で培ったネットワークも新事業の広報・集客に活用できる。 事業運営ノウハウの連続性: 既存事業のSNS発信・マーケティング手法は新事業の集客に転用でき、写真撮影・編集で培った品質管理手法はワークショップ・受注制作の品質保証に直結する。 代表者の専門性: 10年以上の写真実務経験で培った技術力と、プラチナプリント作家としての3年間の実績・ネットワークが、新事業の信頼性と実現可能性を担保する。
B16: 【ある場合】 既存事業からの 「新規性」 | F16: 事業領域の拡大: 既存事業は企業向けの写真・デザインサービス(B to B)から、個人作家・写真愛好家向けの教育・制作支援(B to C)へ拡大。/ 提供形態の転換: クライアント要望に応じたカスタムメイド制作から、体系化されたワークショップ・会員制サービスへ転換。/ 技術の社会化: 代表者が蓄積した技術と既存事業ノウハウを統合し、技術を学べる・使える・継承できる社会的インフラを構築。/ 日本初の総合型: 12技法を網羅し、教育・制作・研究・コミュニティを統合した総合型ラボとして、既存の単一技法・体験型施設とは一線を画す。/ 国際連携の構築: 国内完結型から、台湾・欧米専門ラボとの技術交流・共同研究による連携体制を構築。/ デジタル×アナログ融合: デジタル技術の商業応用から、デジタルネガという「架け橋」技術の開発・提供へ発展。
B21: （４）取組効果 （売上や集客の増加などについて）
B22: 深化・発展により 見込まれる効果 | F22: 【定量効果】 ・売上拡大: 既存事業¥18,640,000から、1年目¥9,000,000(新事業のみ、8ヶ月稼働)、2年目¥13,450,000、3年目¥33,850,000(新事業のみ)へ拡大。既存事業と併行することで収益基盤を強化。 ・営業利益改善: 1年目は施設準備期間(4ヶ月)および初期投資により利益は限定的だが、2年目以降は営業利益率30%以上、3年目¥18,187,500(利益率54%)と大幅改善。既存事業の低収益性を克服。 ・顧客基盤拡大: 年間来訪者数1年目約330名(8ヶ月稼働)、2年目約500名、3年目約1,200名。ワークショップ参加者、暗室会員、コミュニティ会員等の多層的顧客獲得。 ・雇用創出: アシスタント1〜2名の新規雇用。次世代への技術継承を視野に入れた採用を行い、将来的な技術者育成を実現。加えてワークショップ等でアルバイトスタッフを雇用し、地域雇用にも貢献。 【定性効果】 ・ブランド価値向上: 日本唯一の古典技法総合ラボとしての地位確立により、企業ブランド・代表者の認知度が飛躍的に向上。 ・技術的優位性: デジタルネガ技術の標準化、国際技術交流により、競合優位性を確立。 ・社会的インパクト: 日本写真文化の国際競争力向上、若手作家育成、技法継承への貢献。 ・事業の安定化: B to B単一依存からB to C複合事業へ転換し、収益基盤を多様化・安定化。
B31: 効果の定量的説明 | F31: 項目 | I31: 取組前 | L31: 取組後 | O31: 効果を見込む根拠・理由
F32: 年間売上高 | I32: 18640000 | L32: 27640000 | O32: 新事業¥9,000,000(8ヶ月稼働)
F33: 営業利益 | I33: -2230000 | L33: 495000 | O33: 新事業¥2,725,000。新事業により黒字転換
F34: 来訪者数 | I34: 0名 | L34: 約330名 | O34: 新事業のWS参加者+暗室利用者+イベント参加者

Sheet 計画3
B2: （５）実施体制(文字サイズ9pt以上、下枠内に収まるよう記載)
B3: 【実施体制】 代表・総責任者: 木下大輔（株式会社プルスウルトラ代表取締役） ・運営全般統括、デジタルネガ技術開発、ワークショップ講師、作家活動 ・既存事業（広告制作）との並行運営 技術責任者・主任講師: 猪股良文氏（業務提携・常勤相当） ・古典技法ワークショップ全般、暗室運営、プリント制作受注 ・報酬: 営業利益の30%配分による成果報酬型契約 銀塩技術顧問: 久保元幸氏（業務提携・非常勤） ・銀塩プリント受注制作、銀塩技法ワークショップ講師、技術監修 ・報酬: 関与案件収益の40%配分 アシスタント: 未定（1〜2名、2年目以降パート雇用予定） ・受付・予約管理、ワークショップ補助、一般事務 ・次世代への技術継承を視野に入れた採用・育成 外部連携: ・技術連携: 光影手工暗房工作室（台湾）、GOLD・STRET・STUDIOS（オーストラリア） ・学術連携: 東京工芸大学名誉教授 内藤明氏、日本写真芸術学会 高橋則英会長、東京工芸大学芸術学部写真学科 大和田良准教授 ・施設連携:日本カメラ博物館、美術館、美術大学、ギャラリー ・薬品・設備: 高橋藤吉商店やPGIなどの薬品サプライヤー
B19: 【発展の場合】開発等の主担当者について
B20: 氏 名 | H20: 主な研究 開発経歴
B21: 在籍年数
B22: 得意分野
B24: ２．助成事業終了後の収益計画
B25: （１）本取組についての収益計画
B26: 項 目 | E26: 年次 | G26: 金 額 | K26: 算出根拠（価格×数量等の具体的な算式を用いて記入）
B27: 売上高 | E27: １年目 | G27: 8115000 | J27: 円 | K27: ・WS:6回/月×3名/回（充足率50％）×34800円（平均単価）×8ヶ月・レンタル暗室:2500/時間×8時間×3日間××8ヶ月・プリント：65600円（平均単価）×5枚/月×8ヶ月
E28: ２年目 | G28: 21980000 | J28: 円 | K28: ・WS:6回/月 × 4名/回（充足率65%） × ¥34,800 × 12ヶ月・レンタル暗室:2,500/時間 × 8時間 × 8日間 × 12ヶ月・プリント：¥65,600 × 12枚/月 × 12ヶ月・デジタルネガ出力； ¥10,000（平均単価）× 5枚 × 12ヶ月
E29: ３年目 | G29: 34870000 | J29: 円 | K29: ・WS:7回/月 × 4.5名/回（充足率75%） × ¥34,800 × 12ヶ月・¥2,500/時間 × 8時間 × 10日間 × 12ヶ月・プリント：¥65,600 × 23枚/月 × 12ヶ月・デジタルネガ出力； ¥10,000（平均単価）× 10枚 × 12ヶ月
B30: 営業損益等 | E30: １年目 | G30: 321440 | J30: 円 | K30: ¥8,115,200（売上）-¥2,028,800（材料費）-¥4,000,000（固定費）-¥840,000（有牛返済・4ヶ月）-¥787,200（久保氏配分）-¥137,760（猪股氏配分）
E31: ２年目 | G31: 3881976 | J31: 円 | K31: ¥21,988,800（売上）-¥5,497,200（材料費）-¥6,000,000（固定費・12ヶ月）-¥2,112,000（融資返済・12ヶ月）-¥2,833,920（久保氏配分）-¥1,663,704（猪股氏配分）
E32: ３年目 | G32: 6872194 | J32: 円 | K32: ¥34,870,800（売上）-¥8,717,700（材料費）-¥6,000,000（固定費・12ヶ月）-¥1,704,000（融資返済・12ヶ月）-¥2,000,000（暗室シンク設置）-¥1,200,000（アシスタント給与）-¥5,431,680（久保氏配分）-¥2,945,226（猪股氏配分
B33: ※営業損益等→法人：営業損益、個人：収支内訳書の所得金額（㉑）又は青色申告決算書の差引金額（㉝）相当額
B34: （２）他事業等を含む全体の収益計画
B35: 項 目 | E35: 年次 | G35: 金 額 | K35: 算出根拠（価格×数量等の具体的な算式を用いて記入）
B36: 売上高 | E36: １年目 | G36: 26755200 | J36: 円 | K36: ¥8,115,200（新規）+¥18,640,000（既存）
E37: ２年目 | G37: 21988800 | J37: 円 | K37: ¥21,988,800（新規）+¥18,640,000（既存）
E38: ３年目 | G38: 34870800 | J38: 円 | K38: ¥34,870,800（新規）+¥18,640,000（既存）
B39: 営業損益等 | E39: １年目 | G39: -1908560 | J39: 円 | K39: ¥321,440（新規事業営業利益）-¥2,230,000（既存事業営業損失）
E40: ２年目 | G40: 1651976 | J40: 円 | K40: ¥3,881,976（新規事業営業利益）-¥2,230,000（既存事業営業損失）
E41: ３年目 | G41: 4642194 | J41: 円 | K41: ¥6,872,194（新規事業営業利益）-¥2,230,000（既存事業営業損失）
B42: （３）収益計画を達成するための具体的方策
B43: 1年目は基本4事業（ワークショップ・レンタル暗室・受注制作・デジタルネガ出力）で基盤を確立し、2年目からコミュニティ事業を本格化する。3年目に暗室1室を増設し、収益源を多角化する。 顧客育成サイクルによるLTV最大化 「無料体験会→入門WS→中級WS→暗室会員→コミュニティ会員」という顧客ライフサイクルを構築し、顧客単価と継続率を向上させる。ワークショップ受講者を暗室会員へ育成することで、安定的な月次収益を確保する。 デジタルマーケティングによる効率的集客 SEO対策で検索上位表示を獲得し、SNS（Instagram/YouTube）での技法解説動画発信により認知度を向上させる。 プレミアム化戦略による高単価維持 日本唯一の総合型ラボという希少価値、業界トップ技術者による指導、独自のデジタルネガ技術により差別化を実現する。品質保証と技術サポートにより高単価を維持する。 固定費最適化とリスク分散 1年目は3名体制（固定費月¥500,000）で開始し、3年目からアシスタント1名を追加する。成果報酬型配分により売上変動リスクに対応し、既存事業との並行運営で安定性を確保する。

Sheet 計画4
B2: ３．市場動向（事業環境の変化に対する分析・戦略）、創意工夫、独自性
B3: （１）本取組に対する、市場・顧客・競合他社の状況 ※「ポストコロナ等における事業環境変化の前後の比較」という観点を踏まえて記載
B5: コロナ前（〜2019年）の状況 市場はデジタル写真全盛でフィルム・暗室施設は減少傾向にあり、古典技法は「一部のマニア向け」という認識であった。若年層はデジタル中心で学習機会も限定的、総合型の常設施設はほぼ不在という状況であった。 ポストコロナ（2020年〜）の状況と変化 市場の劇的変化: AI画像生成の普及により逆に「手で作る写真」への価値が再認識され、デジタル疲れから物質性への回帰が進んだ。写真アート市場は年率6%成長（2024年78億ドル）、ファインアートプリント市場は年率6.7%成長（2024年21億ドル→2033年38億ドル）を記録し、フィルム販売は2024年「過去数十年で最高」となった。特に2024年11月パリフォトでは古典技法プリントが会場の大部分を占めるほど注目を集めた。 顧客の変化: Z世代・元デジタル作家・キャリアチェンジ層が新規顧客層として出現し、SNSで「学びたい」という声が急増。ワークショップで終わらず継続制作したいというニーズが顕在化した。 競合の変化: 既存施設は体験型中心で継続制作支援は限定的であり、「学んだ後に使える場所」が日本にほぼ不在という市場の空白が明確化。海外では総合型ラボが増加・拡充する一方、日本では施設減少が続き格差が拡大している。 結論: ポストコロナ期は古典写真技法にとって追い風であり、本取り組みの事業機会は拡大している。
B20: （２）上記の分析を踏まえた、本取組への顧客獲得策・市場拡大策 ※助成事業の効果を高めるための創意工夫、企業として独自性を発揮できる点などについても記載
B22: 顧客獲得策：多層的なアプローチにより顧客接点を構築する。入門層には「楽しさ」を体験してもらい、中級層には体系的ワークショッププログラムで深化を促進、上級層にはマスタークラスや展示機会を提供してロイヤル化を図る。これにより「体験→入門WS→中級WS→暗室会員→コミュニティ会員」という顧客育成サイクルを構築し、顧客のライフタイムバリューを最大化する。デジタルマーケティングでは、検索上位表示、SNS(Instagram/Twitter/YouTube)での発信、リターゲティング広告により効率的な集客を実現する。 市場拡大策：東京を拠点として、顧客層と提供サービスを段階的に拡大する。1〜2年目は一般作家・写真愛好家を中心に基盤を確立し、2〜3年目には大学との連携を強化する。多くの大学では古典技法の紹介程度にとどまっているため、より深く学びたい学生をターゲットにした学生向けプログラムを開発・実施する。3年目以降は国際展開準備として海外作家招聘・英語対応を進める。サービス領域拡大では、B to B市場(ギャラリー・美術館・企業向けサービス)、オンラインサービス(デジタルネガ出力通販・動画配信)、研究・出版事業(技法マニュアル・学術論文)へと展開する。 創意工夫・独自性：日本初の総合型モデルとして「学ぶ(ワークショップ)+作る(暗室)+つながる(コミュニティ)」を統合し、作家のワンストップ支援を実現する。デジタル×アナログ融合技術では、独自開発の階調管理システムと用紙別・技法別プロファイルにより、従来の「アナログ vs デジタル」という対立構造を超越した品質保証を実現。段階的成長戦略により、1年目は1室体制で開始し、4〜6年目に2室目増設を準備することでリスクを最小化する。現役作家(木下)×トップ技術者(猪股・久保)という日本唯一の組合せと、台湾・欧米との国際ネットワークにより、国内外の最新技術と知見を統合する。
B38: ４．今後の展望
B39: 本取組の実施を通して得た収益や知見を、助成終了後にどう活かしていくか（将来的な経営展開をどう考えているか）
B41: 短期(1〜3年目): 基盤確立期：1年目は東京に1室体制で開業し、運営システムを確立、初年度黒字化を達成する。2〜3年目はサービス拡充と会員拡大を進め、「日本唯一の総合型ラボ」としての地位を確立する。美術大学・ギャラリー・国際ラボとの連携を本格化する。 中期(4〜6年目): 拡大・深化期：研究・出版事業(技法マニュアル、学術論文)と大学・研究機関との共同研究を進める。オンラインサービス(デジタルネガ出力全国対応、技法解説動画配信)とB to B市場(ギャラリー・美術館・企業向けプログラム)へ展開する。6年目に2室目増設を実施する。 長期(7年目〜): 深化・国際化期：東京拠点の深化と国際展開を進める。アジア圏との技術交流定期化、英語対応ワークショップ、海外作家レジデンスプログラムを確立する。 知見の活用：教育ノウハウは出版・オンライン講座・大学講師派遣へ、デジタルネガ技術は技術ライセンス・コンサルティングへ、暗室運営ノウハウは他施設コンサルティングへ、コミュニティ形成手法はプラットフォーム事業へと展開し、持続可能な成長を実現する。 10年後ビジョン：日本の写真文化を国際水準に引き上げる社会的インフラとして確立する。「日本から再び、世界を驚かせる写真表現が生まれる土壌をつくる」という理念のもと、次世代の作家が古典技法を武器に国際舞台で活躍する基盤を構築する。
B56: 5．米国関税措置による影響と対策（申請者３シートの５.決算状況(1)要件確認のうち、申請要件でcを選択した方のみ記入）
B57: （１）米国関税措置によりどの程度影響を受ける見込みか。また、それに対しどう具体的に対策を行う予定か。
B64: （２）「2. 助成事業終了後の収益計画」に記載の売上高を達成できる見込みはあるか。※その理由も記載

Sheet 工程
A2: Ⅲ 資金計画
A3: １．スケジュール（工程）
A4: 注 意 事 項 | D4: ①具体的な作業項目、資金支出明細の番号（原－1、機－1・・・）を記入 ②自社作業に該当する期間は○、他社作業に該当する期間は●を記入 ③本事業の全体像が分かるよう、経費が発生しない作業も記入
A7: 事 業 終 了 予 定 日 | D7: =IF(表紙!C40="","",表紙!C40)
A9: （１）事業スケジュール（実施時期も含めてご説明願います）
A20: （２）事業スケジュールに沿った作業項目
A21: No. | B21: 作業項目 | J21: 支出 番号
A23: 1
A24: 2
A25: 3
A26: 4
A27: 5
A28: 6
A29: 7
A30: 8
A31: 9
A32: 10
A33: 11
A34: 12

Sheet 原材料
B1: ２．資金支出明細
B2: 【原材料・副資材費】
C3: <留意事項>
B4: ・１契約30万円以上の項目は、見積書・カタログ等の提出が必要です。
B5: ・１契約100万円以上の項目は、相見積の結果を「相見積」シートに記載してください。
AM7: 【税抜】 | AS7: 【税抜】 | AY7: 【税込】 | BM7: （単位：円）
B8: 支出 | F8: 品名 | P8: 用途 | AD8: 調達 | AG8: 数量 | AM8: 単価 | AS8: 助成対象経費 | AY8: 助成事業に | BE8: ＜留意事項＞
B9: 番号 | P9: (取組に必要な理由) | AD9: 方法 | AG9: (A) | AM9: (B) | AS9: （A）×(B) | AY9: 要する経費 | BE9: 見積書 | BH9: 相見積 | BK9: 単価
B10: 原-1 | F10: ｼｭｳ酸鉄(Ⅱ)2H2O（500g) | AD10: (選択) | AG10: 5 | AM10: 3500 | AS10: =IF(AM10="","",AG10*AM10) -> 17500 | AY10: =IF(AM10="","",ROUNDDOWN(AG10*AM10*1.1,0)) -> 19250 | BE10: =IF(AS10="","",IF(AS10>=300000,"必要","")) | BH10: =IF(AS10="","",IF(AS10>=1000000,"必要","")) | BK10: =IF(AM10="","",IF(AM10<100000,"×","〇")) -> ×
B11: 原-2 | F11: ｼｭｳ酸(無水)（500g) | AD11: (選択) | AG11: 5 | AM11: 4500 | AS11: =IF(AM11="","",AG11*AM11) -> 22500 | AY11: =IF(AM11="","",ROUNDDOWN(AG11*AM11*1.1,0)) -> 24750 | BE11: =IF(AS11="","",IF(AS11>=300000,"必要","")) | BH11: =IF(AS11="","",IF(AS11>=1000000,"必要","")) | BK11: =IF(AM11="","",IF(AM11<100000,"×","〇")) -> ×
B12: 原-3 | F12: 過酸化水素水(30%)(500ml） | AD12: (選択) | AG12: 7 | AM12: 5000 | AS12: =IF(AM12="","",AG12*AM12) -> 35000 | AY12: =IF(AM12="","",ROUNDDOWN(AG12*AM12*1.1,0)) -> 38500 | BE12: =IF(AS12="","",IF(AS12>=300000,"必要","")) | BH12: =IF(AS12="","",IF(AS12>=1000000,"必要","")) | BK12: =IF(AM12="","",IF(AM12<100000,"×","〇")) -> ×
B13: 原-4 | F13: AGガード | AD13: (選択) | AG13: 1 | AM13: 4130 | AS13: =IF(AM13="","",AG13*AM13) -> 4130 | AY13: =IF(AM13="","",ROUNDDOWN(AG13*AM13*1.1,0)) -> 4543 | BE13: =IF(AS13="","",IF(AS13>=300000,"必要","")) | BH13: =IF(AS13="","",IF(AS13>=1000000,"必要","")) | BK13: =IF(AM13="","",IF(AM13<100000,"×","〇")) -> ×
B14: 原-5 | F14: エチレンジアミン四酢酸 二水素ナトリウム二水和物(2NA）（500g) | AD14: (選択) | AG14: 1 | AM14: 5300 | AS14: =IF(AM14="","",AG14*AM14) -> 5300 | AY14: =IF(AM14="","",ROUNDDOWN(AG14*AM14*1.1,0)) -> 5830 | BE14: =IF(AS14="","",IF(AS14>=300000,"必要","")) | BH14: =IF(AS14="","",IF(AS14>=1000000,"必要","")) | BK14: =IF(AM14="","",IF(AM14<100000,"×","〇")) -> ×
B15: 原-6 | F15: エチレンジアミン四酢酸 二水素ナトリウム四水和物(4NA) | AD15: (選択) | AG15: 1 | AM15: 4130 | AS15: =IF(AM15="","",AG15*AM15) -> 4130 | AY15: =IF(AM15="","",ROUNDDOWN(AG15*AM15*1.1,0)) -> 4543 | BE15: =IF(AS15="","",IF(AS15>=300000,"必要","")) | BH15: =IF(AS15="","",IF(AS15>=1000000,"必要","")) | BK15: =IF(AM15="","",IF(AM15<100000,"×","〇")) -> ×
B16: 原-7 | F16: 炭酸水素ナトリウム(重曹) | AD16: (選択) | AG16: 1 | AM16: 4100 | AS16: =IF(AM16="","",AG16*AM16) -> 4100 | AY16: =IF(AM16="","",ROUNDDOWN(AG16*AM16*1.1,0)) -> 4510 | BE16: =IF(AS16="","",IF(AS16>=300000,"必要","")) | BH16: =IF(AS16="","",IF(AS16>=1000000,"必要","")) | BK16: =IF(AM16="","",IF(AM16<100000,"×","〇")) -> ×
B17: 原-8 | F17: Tween20(10%) | AD17: (選択) | AG17: 1 | AM17: 1640 | AS17: =IF(AM17="","",AG17*AM17) -> 1640 | AY17: =IF(AM17="","",ROUNDDOWN(AG17*AM17*1.1,0)) -> 1804 | BE17: =IF(AS17="","",IF(AS17>=300000,"必要","")) | BH17: =IF(AS17="","",IF(AS17>=1000000,"必要","")) | BK17: =IF(AM17="","",IF(AM17<100000,"×","〇")) -> ×
B18: 原-9 | F18: アシッドイエロー23(タートラジン) | AD18: (選択) | AG18: 1 | AM18: 4720 | AS18: =IF(AM18="","",AG18*AM18) -> 4720 | AY18: =IF(AM18="","",ROUNDDOWN(AG18*AM18*1.1,0)) -> 5192 | BE18: =IF(AS18="","",IF(AS18>=300000,"必要","")) | BH18: =IF(AS18="","",IF(AS18>=1000000,"必要","")) | BK18: =IF(AM18="","",IF(AM18<100000,"×","〇")) -> ×
B19: 原-10 | F19: アシッドレッド94(ローズベンガル) | AD19: (選択) | AG19: 1 | AM19: 6600 | AS19: =IF(AM19="","",AG19*AM19) -> 6600 | AY19: =IF(AM19="","",ROUNDDOWN(AG19*AM19*1.1,0)) -> 7260 | BE19: =IF(AS19="","",IF(AS19>=300000,"必要","")) | BH19: =IF(AS19="","",IF(AS19>=1000000,"必要","")) | BK19: =IF(AM19="","",IF(AM19<100000,"×","〇")) -> ×
B20: 原-11 | F20: エリスロシン(顕微鏡用)(赤色) | AD20: (選択) | AG20: 1 | AM20: 6420 | AS20: =IF(AM20="","",AG20*AM20) -> 6420 | AY20: =IF(AM20="","",ROUNDDOWN(AG20*AM20*1.1,0)) -> 7062 | BE20: =IF(AS20="","",IF(AS20>=300000,"必要","")) | BH20: =IF(AS20="","",IF(AS20>=1000000,"必要","")) | BK20: =IF(AM20="","",IF(AM20<100000,"×","〇")) -> ×
B21: 原-12 | F21: マラカイトグリーンシュウ酸塩 | AD21: (選択) | AG21: 1 | AM21: 2100 | AS21: =IF(AM21="","",AG21*AM21) -> 2100 | AY21: =IF(AM21="","",ROUNDDOWN(AG21*AM21*1.1,0)) -> 2310 | BE21: =IF(AS21="","",IF(AS21>=300000,"必要","")) | BH21: =IF(AS21="","",IF(AS21>=1000000,"必要","")) | BK21: =IF(AM21="","",IF(AM21<100000,"×","〇")) -> ×
... B38: 原-22 | F38: 硝酸銀(Ⅰ) | AD38: (選択) | AG38: 5 | AM38: 135000 | AS38: =IF(AM38="","",AG38*AM38) -> 675000 | AY38: =IF(AM38="","",ROUNDDOWN(AG38*AM38*1.1,0)) -> 742500 | BE38: =IF(AS38="","",IF(AS38>=300000,"必要","")) -> 必要 | BH38: =IF(AS38="","",IF(AS38>=1000000,"必要","")) | BK38: =IF(AM38="","",IF(AM38<100000,"×","〇")) -> 〇
B39: 原-22 | F39: L-アスコルビン酸 | AD39: (選択) | AS39: =IF(AM39="","",AG39*AM39) | AY39: =IF(AM39="","",ROUNDDOWN(AG39*AM39*1.1,0)) | BE39: =IF(AS39="","",IF(AS39>=300000,"必要","")) | BH39: =IF(AS39="","",IF(AS39>=1000000,"必要","")) | BK39: =IF(AM39="","",IF(AM39<100000,"×","〇"))
B40: 原-22 | F40: 亜硫酸ナトリウム(無水) | AD40: (選択) | AG40: 1 | AM40: 1300 | AS40: =IF(AM40="","",AG40*AM40) -> 1300 | AY40: =IF(AM40="","",ROUNDDOWN(AG40*AM40*1.1,0)) -> 1430 | BE40: =IF(AS40="","",IF(AS40>=300000,"必要","")) | BH40: =IF(AS40="","",IF(AS40>=1000000,"必要","")) | BK40: =IF(AM40="","",IF(AM40<100000,"×","〇")) -> ×
B41: 原-22 | F41: 塩化金(Ⅲ)酸4水和物（テトラクロロ金(III)酸四水和物） | AD41: (選択) | AG41: 2 | AM41: 17500 | AS41: =IF(AM41="","",AG41*AM41) -> 35000 | AY41: =IF(AM41="","",ROUNDDOWN(AG41*AM41*1.1,0)) -> 38500 | BE41: =IF(AS41="","",IF(AS41>=300000,"必要","")) | BH41: =IF(AS41="","",IF(AS41>=1000000,"必要","")) | BK41: =IF(AM41="","",IF(AM41<100000,"×","〇")) -> ×
B42: 原-22 | F42: 塩化ナトリウム(試薬) | AD42: (選択) | AG42: 1 | AM42: 1100 | AS42: =IF(AM42="","",AG42*AM42) -> 1100 | AY42: =IF(AM42="","",ROUNDDOWN(AG42*AM42*1.1,0)) -> 1210 | BE42: =IF(AS42="","",IF(AS42>=300000,"必要","")) | BH42: =IF(AS42="","",IF(AS42>=1000000,"必要","")) | BK42: =IF(AM42="","",IF(AM42<100000,"×","〇")) -> ×
B43: 原-22 | F43: 過酸化水素水(35%) | AD43: (選択) | AG43: 1 | AM43: 1100 | AS43: =IF(AM43="","",AG43*AM43) -> 1100 | AY43: =IF(AM43="","",ROUNDDOWN(AG43*AM43*1.1,0)) -> 1210 | BE43: =IF(AS43="","",IF(AS43>=300000,"必要","")) | BH43: =IF(AS43="","",IF(AS43>=1000000,"必要","")) | BK43: =IF(AM43="","",IF(AM43<100000,"×","〇")) -> ×
B44: 原-22 | F44: クエン酸(試薬) | AD44: (選択) | AG44: 1 | AM44: 2100 | AS44: =IF(AM44="","",AG44*AM44) -> 2100 | AY44: =IF(AM44="","",ROUNDDOWN(AG44*AM44*1.1,0)) -> 2310 | BE44: =IF(AS44="","",IF(AS44>=300000,"必要","")) | BH44: =IF(AS44="","",IF(AS44>=1000000,"必要","")) | BK44: =IF(AM44="","",IF(AM44<100000,"×","〇")) -> ×
B45: 原-22 | F45: クエン酸(99.5%)(無水)(食品添加物) | AD45: (選択) | AS45: =IF(AM45="","",AG45*AM45) | AY45: =IF(AM45="","",ROUNDDOWN(AG45*AM45*1.1,0)) | BE45: =IF(AS45="","",IF(AS45>=300000,"必要","")) | BH45: =IF(AS45="","",IF(AS45>=1000000,"必要","")) | BK45: =IF(AM45="","",IF(AM45<100000,"×","〇"))
B46: 原-22 | F46: クエン酸鉄(III)アンモニウム(緑色) | AD46: (選択) | AG46: 1 | AM46: 12800 | AS46: =IF(AM46="","",AG46*AM46) -> 12800 | AY46: =IF(AM46="","",ROUNDDOWN(AG46*AM46*1.1,0)) -> 14080 | BE46: =IF(AS46="","",IF(AS46>=300000,"必要","")) | BH46: =IF(AS46="","",IF(AS46>=1000000,"必要","")) | BK46: =IF(AM46="","",IF(AM46<100000,"×","〇")) -> ×
B47: 原-22 | F47: 酢酸(99%) | AD47: (選択) | AG47: 1 | AM47: 1200 | AS47: =IF(AM47="","",AG47*AM47) -> 1200 | AY47: =IF(AM47="","",ROUNDDOWN(AG47*AM47*1.1,0)) -> 1320 | BE47: =IF(AS47="","",IF(AS47>=300000,"必要","")) | BH47: =IF(AS47="","",IF(AS47>=1000000,"必要","")) | BK47: =IF(AM47="","",IF(AM47<100000,"×","〇")) -> ×
B48: 原-22 | F48: 酒石酸 | AD48: (選択) | AG48: 1 | AM48: 2600 | AS48: =IF(AM48="","",AG48*AM48) -> 2600 | AY48: =IF(AM48="","",ROUNDDOWN(AG48*AM48*1.1,0)) -> 2860 | BE48: =IF(AS48="","",IF(AS48>=300000,"必要","")) | BH48: =IF(AS48="","",IF(AS48>=1000000,"必要","")) | BK48: =IF(AM48="","",IF(AM48<100000,"×","〇")) -> ×
B49: 原-22 | F49: 硝酸（1.38） | AD49: (選択) | AG49: 1 | AM49: 1300 | AS49: =IF(AM49="","",AG49*AM49) -> 1300 | AY49: =IF(AM49="","",ROUNDDOWN(AG49*AM49*1.1,0)) -> 1430 | BE49: =IF(AS49="","",IF(AS49>=300000,"必要","")) | BH49: =IF(AS49="","",IF(AS49>=1000000,"必要","")) | BK49: =IF(AM49="","",IF(AM49<100000,"×","〇")) -> ×
B50: 原-22 | F50: 食塩 | AD50: (選択) | AG50: 1 | AS50: =IF(AM50="","",AG50*AM50) | AY50: =IF(AM50="","",ROUNDDOWN(AG50*AM50*1.1,0)) | BE50: =IF(AS50="","",IF(AS50>=300000,"必要","")) | BH50: =IF(AS50="","",IF(AS50>=1000000,"必要","")) | BK50: =IF(AM50="","",IF(AM50<100000,"×","〇"))
B51: 原-22 | F51: 赤血塩(フェリシアン化カリウム)(ヘキサシアニド鉄(III)酸カリウム) | AD51: (選択) | AG51: 1 | AM51: 2200 | AS51: =IF(AM51="","",AG51*AM51) -> 2200 | AY51: =IF(AM51="","",ROUNDDOWN(AG51*AM51*1.1,0)) -> 2420 | BE51: =IF(AS51="","",IF(AS51>=300000,"必要","")) | BH51: =IF(AS51="","",IF(AS51>=1000000,"必要","")) | BK51: =IF(AM51="","",IF(AM51<100000,"×","〇")) -> ×
B52: 原-22 | F52: 炭酸ナトリウム(無水) | AD52: (選択) | AG52: 1 | AM52: 1170 | AS52: =IF(AM52="","",AG52*AM52) -> 1170 | AY52: =IF(AM52="","",ROUNDDOWN(AG52*AM52*1.1,0)) -> 1287 | BE52: =IF(AS52="","",IF(AS52>=300000,"必要","")) | BH52: =IF(AS52="","",IF(AS52>=1000000,"必要","")) | BK52: =IF(AM52="","",IF(AM52<100000,"×","〇")) -> ×
B53: 原-22 | F53: チオ硫酸ナトリウム(ハイポ） | AD53: (選択) | AG53: 5 | AM53: 1650 | AS53: =IF(AM53="","",AG53*AM53) -> 8250 | AY53: =IF(AM53="","",ROUNDDOWN(AG53*AM53*1.1,0)) -> 9075 | BE53: =IF(AS53="","",IF(AS53>=300000,"必要","")) | BH53: =IF(AS53="","",IF(AS53>=1000000,"必要","")) | BK53: =IF(AM53="","",IF(AM53<100000,"×","〇")) -> ×
B54: 原-22 | F54: ハイポクリア | AD54: (選択) | AS54: =IF(AM54="","",AG54*AM54) | AY54: =IF(AM54="","",ROUNDDOWN(AG54*AM54*1.1,0)) | BE54: =IF(AS54="","",IF(AS54>=300000,"必要","")) | BH54: =IF(AS54="","",IF(AS54>=1000000,"必要","")) | BK54: =IF(AM54="","",IF(AM54<100000,"×","〇"))
B55: 原-22 | F55: ほう砂(ホウ酸ナトリウム) | AD55: (選択) | AG55: 1 | AM55: 1600 | AS55: =IF(AM55="","",AG55*AM55) -> 1600 | AY55: =IF(AM55="","",ROUNDDOWN(AG55*AM55*1.1,0)) -> 1760 | BE55: =IF(AS55="","",IF(AS55>=300000,"必要","")) | BH55: =IF(AS55="","",IF(AS55>=1000000,"必要","")) | BK55: =IF(AM55="","",IF(AM55<100000,"×","〇")) -> ×
B56: 原-22 | F56: 炭酸ナトリウム（アルカリ剤(ナボックス) | AD56: (選択) | AG56: 1 | AM56: 1400 | AS56: =IF(AM56="","",AG56*AM56) -> 1400 | AY56: =IF(AM56="","",ROUNDDOWN(AG56*AM56*1.1,0)) -> 1540 | BE56: =IF(AS56="","",IF(AS56>=300000,"必要","")) | BH56: =IF(AS56="","",IF(AS56>=1000000,"必要","")) | BK56: =IF(AM56="","",IF(AM56<100000,"×","〇")) -> ×
B57: 原-22 | F57: 臭素 | AD57: (選択) | AG57: 1 | AM57: 5250 | AS57: =IF(AM57="","",AG57*AM57) -> 5250 | AY57: =IF(AM57="","",ROUNDDOWN(AG57*AM57*1.1,0)) -> 5775 | BE57: =IF(AS57="","",IF(AS57>=300000,"必要","")) | BH57: =IF(AS57="","",IF(AS57>=1000000,"必要","")) | BK57: =IF(AM57="","",IF(AM57<100000,"×","〇")) -> ×
...

Sheet 機械
B1: 【機械装置・工具器具費】
C2: ＜留意事項＞
C3: ・１契約30万円以上の項目は、見積書・カタログ等の提出が必要です。
C4: ・１契約100万円以上の項目は、相見積の結果を「相見積」シートに記載してください。
C5: ・１品あたりの金額(単価)が税抜10万円未満の経費は、申請できません。
C6: ※調達方法がリース又はレンタルの場合、(A)に月数、(B)に月額料金を記入してください。
AM8: 【税抜】 | AS8: 【税抜】 | AY8: 【税込】 | BM8: （単位：円）
B9: 支出 | F9: 品名 | P9: 用途 | AD9: 調達 | AG9: 数量 | AM9: 単価 | AS9: 助成対象経費 | AY9: 助成事業に | BE9: ＜留意事項＞
B10: 番号 | P10: (取組に必要な理由) | AD10: 方法 | AG10: (A) | AM10: (B) | AS10: （A）×(B) | AY10: 要する経費 | BE10: 見積書 | BH10: 相見積 | BK10: 単価
B11: 機-1 | F11: 耐震ステンレス薬品庫(SUS430・縦型) | AD11: 購入 | AG11: 1 | AM11: 134000 | AS11: =IF(AM11="","",AG11*AM11) -> 134000 | AY11: =IF(AM11="","",ROUNDDOWN(AG11*AM11*1.1,0)) -> 147400 | BE11: =IF(AS11="","",IF(AS11>=300000,"必要","")) | BH11: =IF(AS11="","",IF(AS11>=1000000,"必要","")) | BK11: =IF(AM11="","",IF(AM11<100000,"×","〇")) -> 〇
B12: 機-2 | F12: 防爆冷凍冷蔵庫 LGUEX-1500 | AD12: 購入 | AG12: 1 | AM12: 360000 | AS12: =IF(AM12="","",AG12*AM12) -> 360000 | AY12: =IF(AM12="","",ROUNDDOWN(AG12*AM12*1.1,0)) -> 396000 | BE12: =IF(AS12="","",IF(AS12>=300000,"必要","")) -> 必要 | BH12: =IF(AS12="","",IF(AS12>=1000000,"必要","")) | BK12: =IF(AM12="","",IF(AM12<100000,"×","〇")) -> 〇
B13: 機-3 | F13: フロストドライデシケーター | AD13: (選択) | AG13: 1 | AM13: 319000 | AS13: =IF(AM13="","",AG13*AM13) -> 319000 | AY13: =IF(AM13="","",ROUNDDOWN(AG13*AM13*1.1,0)) -> 350900 | BE13: =IF(AS13="","",IF(AS13>=300000,"必要","")) -> 必要 | BH13: =IF(AS13="","",IF(AS13>=1000000,"必要","")) | BK13: =IF(AM13="","",IF(AM13<100000,"×","〇")) -> 〇
B14: 機-4 | F14: 分光計-C7000 | AD14: (選択) | AG14: 1 | AM14: 367000 | AS14: =IF(AM14="","",AG14*AM14) -> 367000 | AY14: =IF(AM14="","",ROUNDDOWN(AG14*AM14*1.1,0)) -> 403700 | BE14: =IF(AS14="","",IF(AS14>=300000,"必要","")) -> 必要 | BH14: =IF(AS14="","",IF(AS14>=1000000,"必要","")) | BK14: =IF(AM14="","",IF(AM14<100000,"×","〇")) -> 〇
B15: 機-5 | AD15: (選択) | AS15: =IF(AM15="","",AG15*AM15) | AY15: =IF(AM15="","",ROUNDDOWN(AG15*AM15*1.1,0)) | BE15: =IF(AS15="","",IF(AS15>=300000,"必要","")) | BH15: =IF(AS15="","",IF(AS15>=1000000,"必要","")) | BK15: =IF(AM15="","",IF(AM15<100000,"×","〇"))
AM16: 合計 | AS16: =SUM(AS11:AX15) -> 1180000 | AY16: =SUM(AY11:BD15) -> 1298000
B18: ＜機械装置・工具器具購入計画書＞
C19: ・調達方法で「購入」を選択した、１契約100万円以上（税抜）の項目について記載してください。
C20: ・表が足りない場合は、印刷範囲を広げて使用欄を増やしてください。
B21: 支出番号 | K21: 品名 | AL21: 購入先企業名
B22: 規格（メーカー・型番等）
B23: 設置場所（所在地）
B24: 購入予定時期 | P24: 令和 年 月
B25: 購入が必要な理由
B26: 上記購入先は、自社と資本関係、役員または従業員の兼務、自社の代表者３親等以内の親族による経営ではない。 | BF26: 選択してください

Sheet 委託
B1: 【委託・外注費】
C2: <留意事項>
C3: ・１契約30万円以上の項目は、見積書・カタログ等の提出が必要です。
C4: ・１契約100万円以上の項目は、相見積の結果を「相見積」シートに記載してください。
AM7: 【税抜】 | AS7: 【税抜】 | AY7: 【税込】 | BM7: （単位：円）
B8: 支出 | F8: 品名 | P8: 用途 | AD8: 調達 | AG8: 数量 | AM8: 単価 | AS8: 助成対象経費 | AY8: 助成事業に | BE8: ＜留意事項＞
B9: 番号 | P9: (取組に必要な理由) | AD9: 方法 | AG9: (A) | AM9: (B) | AS9: （A）×(B) | AY9: 要する経費 | BE9: 見積書 | BH9: 相見積 | BK9: 単価
B10: 委-1 | AD10: (選択) | AS10: =IF(AM10="","",AG10*AM10) | AY10: =IF(AM10="","",ROUNDDOWN(AG10*AM10*1.1,0)) | BE10: =IF(AS10="","",IF(AS10>=300000,"必要","")) | BH10: =IF(AS10="","",IF(AS10>=1000000,"必要","")) | BK10: =IF(AM10="","",IF(AM10<100000,"×","〇"))
B11: 委-2 | AD11: (選択) | AS11: =IF(AM11="","",AG11*AM11) | AY11: =IF(AM11="","",ROUNDDOWN(AG11*AM11*1.1,0)) | BE11: =IF(AS11="","",IF(AS11>=300000,"必要","")) | BH11: =IF(AS11="","",IF(AS11>=1000000,"必要","")) | BK11: =IF(AM11="","",IF(AM11<100000,"×","〇"))
B12: 委-3 | AD12: (選択) | AS12: =IF(AM12="","",AG12*AM12) | AY12: =IF(AM12="","",ROUNDDOWN(AG12*AM12*1.1,0)) | BE12: =IF(AS12="","",IF(AS12>=300000,"必要","")) | BH12: =IF(AS12="","",IF(AS12>=1000000,"必要","")) | BK12: =IF(AM12="","",IF(AM12<100000,"×","〇"))
B13: 委-4 | AD13: (選択) | AS13: =IF(AM13="","",AG13*AM13) | AY13: =IF(AM13="","",ROUNDDOWN(AG13*AM13*1.1,0)) | BE13: =IF(AS13="","",IF(AS13>=300000,"必要","")) | BH13: =IF(AS13="","",IF(AS13>=1000000,"必要","")) | BK13: =IF(AM13="","",IF(AM13<100000,"×","〇"))
B14: 委-5 | AD14: (選択) | AS14: =IF(AM14="","",AG14*AM14) | AY14: =IF(AM14="","",ROUNDDOWN(AG14*AM14*1.1,0)) | BE14: =IF(AS14="","",IF(AS14>=300000,"必要","")) | BH14: =IF(AS14="","",IF(AS14>=1000000,"必要","")) | BK14: =IF(AM14="","",IF(AM14<100000,"×","〇"))
AM15: 合計 | AS15: =SUM(AS10:AX14) -> 0 | AY15: =SUM(AY10:BD14) -> 0
B16: ＜委託・外注計画書＞
C17: ・計上した全ての委託・外注先について記載してください。
C18: ・表が足りない場合は、印刷範囲を広げて使用欄を増やしてください。
B19: 支出番号 | K19: 委託・外注先
B20: 委託・外注内容
B21: 契約予定期間 | P21: 令和 年 月 ～ 令和 年 月
B22: 選定理由
B23: 上記委託先は、自社と資本関係、役員または従業員の兼務、自社の代表者３親等以内の親族による経営ではない。 | BF23: 選択してください

Sheet 財産権
B1: 【産業財産権出願・導入費】
C2: <留意事項>
B3: ・１契約あたり30万円以上の項目は、申請時に見積書・カタログ等の提出が必要です。 | C3: ・１契約30万円以上の項目は、見積書・カタログ等の提出が必要です。
B4: ・１契約あたり100万円以上の項目は、相見積の結果を「相見積」シートに記載してください。 | C4: ・１契約100万円以上の項目は、相見積の結果を「相見積」シートに記載してください。
AM7: 【税抜】 | AS7: 【税抜】 | AY7: 【税込】 | BM7: （単位：円）
B8: 支出 | F8: 品名 | P8: 用途 | AD8: 調達 | AG8: 数量 | AM8: 単価 | AS8: 助成対象経費 | AY8: 助成事業に | BE8: ＜留意事項＞
B9: 番号 | P9: (取組に必要な理由) | AD9: 方法 | AG9: (A) | AM9: (B) | AS9: （A）×(B) | AY9: 要する経費 | BE9: 見積書 | BH9: 相見積 | BK9: 単価
B10: 産-1 | AD10: (選択) | AS10: =IF(AM10="","",AG10*AM10) | AY10: =IF(AM10="","",ROUNDDOWN(AG10*AM10*1.1,0)) | BE10: =IF(AS10="","",IF(AS10>=300000,"必要","")) | BH10: =IF(AS10="","",IF(AS10>=1000000,"必要","")) | BK10: =IF(AM10="","",IF(AM10<100000,"×","〇"))
B11: 産-2 | AD11: (選択) | AS11: =IF(AM11="","",AG11*AM11) | AY11: =IF(AM11="","",ROUNDDOWN(AG11*AM11*1.1,0)) | BE11: =IF(AS11="","",IF(AS11>=300000,"必要","")) | BH11: =IF(AS11="","",IF(AS11>=1000000,"必要","")) | BK11: =IF(AM11="","",IF(AM11<100000,"×","〇"))
B12: 産-3 | AD12: (選択) | AS12: =IF(AM12="","",AG12*AM12) | AY12: =IF(AM12="","",ROUNDDOWN(AG12*AM12*1.1,0)) | BE12: =IF(AS12="","",IF(AS12>=300000,"必要","")) | BH12: =IF(AS12="","",IF(AS12>=1000000,"必要","")) | BK12: =IF(AM12="","",IF(AM12<100000,"×","〇"))
B13: 産-4 | AD13: (選択) | AS13: =IF(AM13="","",AG13*AM13) | AY13: =IF(AM13="","",ROUNDDOWN(AG13*AM13*1.1,0)) | BE13: =IF(AS13="","",IF(AS13>=300000,"必要","")) | BH13: =IF(AS13="","",IF(AS13>=1000000,"必要","")) | BK13: =IF(AM13="","",IF(AM13<100000,"×","〇"))
B14: 産-5 | AD14: (選択) | AS14: =IF(AM14="","",AG14*AM14) | AY14: =IF(AM14="","",ROUNDDOWN(AG14*AM14*1.1,0)) | BE14: =IF(AS14="","",IF(AS14>=300000,"必要","")) | BH14: =IF(AS14="","",IF(AS14>=1000000,"必要","")) | BK14: =IF(AM14="","",IF(AM14<100000,"×","〇"))
AM15: 合計 | AS15: =SUM(AS10:AX14) -> 0 | AY15: =SUM(AY10:BD14) -> 0
B16: 〈産業財産権（特許権、実用新案権、意匠権、商標権）詳細〉
B17: （１）先行技術調査の結果（特許情報プラットフォームJ-PlatPat等により検索）
B18: 類似特許番号
B21: 類似特許との相違点
B25: （２）今回の取組に必要な産業財産権を出願又は保有しているか | AH25: (選択)
B26: ※「はい」の場合、それはどのような権利か | AH26: (選択)
AH27: 公開番号又は登録番号等
B28: （３）今回の取組において、他社が保有する産業財産権の実施許諾を受ける予定か | AH28: (選択)
B29: ※「はい」の場合、それはどのような権利か | AH29: (選択)
AH30: 公開番号又は登録番号等
B31: （４）今回の取組の成果を産業財産権として出願する予定か | AH31: (選択)

Sheet 規格
B1: 【規格等認証・登録費】
C2: <留意事項>
C3: ・１契約30万円以上の項目は、見積書・カタログ等の提出が必要です。
C4: ・１契約100万円以上の項目は、相見積の結果を「相見積」シートに記載してください。
AM7: 【税抜】 | AS7: 【税抜】 | AY7: 【税込】 | BM7: （単位：円）
B8: 支出 | F8: 品名 | P8: 用途 | AD8: 調達 | AG8: 数量 | AM8: 単価 | AS8: 助成対象経費 | AY8: 助成事業に | BE8: ＜留意事項＞
B9: 番号 | P9: (取組に必要な理由) | AD9: 方法 | AG9: (A) | AM9: (B) | AS9: （A）×(B) | AY9: 要する経費 | BE9: 見積書 | BH9: 相見積 | BK9: 単価
B10: 規-1 | AD10: (選択) | AS10: =IF(AM10="","",AG10*AM10) | AY10: =IF(AM10="","",ROUNDDOWN(AG10*AM10*1.1,0)) | BE10: =IF(AS10="","",IF(AS10>=300000,"必要","")) | BH10: =IF(AS10="","",IF(AS10>=1000000,"必要","")) | BK10: =IF(AM10="","",IF(AM10<100000,"×","〇"))
B11: 規-2 | AD11: (選択) | AS11: =IF(AM11="","",AG11*AM11) | AY11: =IF(AM11="","",ROUNDDOWN(AG11*AM11*1.1,0)) | BE11: =IF(AS11="","",IF(AS11>=300000,"必要","")) | BH11: =IF(AS11="","",IF(AS11>=1000000,"必要","")) | BK11: =IF(AM11="","",IF(AM11<100000,"×","〇"))
B12: 規-3 | AD12: (選択) | AS12: =IF(AM12="","",AG12*AM12) | AY12: =IF(AM12="","",ROUNDDOWN(AG12*AM12*1.1,0)) | BE12: =IF(AS12="","",IF(AS12>=300000,"必要","")) | BH12: =IF(AS12="","",IF(AS12>=1000000,"必要","")) | BK12: =IF(AM12="","",IF(AM12<100000,"×","〇"))
B13: 規-4 | AD13: (選択) | AS13: =IF(AM13="","",AG13*AM13) | AY13: =IF(AM13="","",ROUNDDOWN(AG13*AM13*1.1,0)) | BE13: =IF(AS13="","",IF(AS13>=300000,"必要","")) | BH13: =IF(AS13="","",IF(AS13>=1000000,"必要","")) | BK13: =IF(AM13="","",IF(AM13<100000,"×","〇"))
B14: 規-5 | AD14: (選択) | AS14: =IF(AM14="","",AG14*AM14) | AY14: =IF(AM14="","",ROUNDDOWN(AG14*AM14*1.1,0)) | BE14: =IF(AS14="","",IF(AS14>=300000,"必要","")) | BH14: =IF(AS14="","",IF(AS14>=1000000,"必要","")) | BK14: =IF(AM14="","",IF(AM14<100000,"×","〇"))
AM15: 合計 | AS15: =SUM(AS10:AX14) -> 0 | AY15: =SUM(AY10:BD14) -> 0
B16: ＜規格等認証・登録計画書＞
C17: ・計上した全ての経費について記載してください。
C18: ・表が足りない場合は、印刷範囲を広げて使用欄を増やしてください。
B19: 支出番号 | K19: 委託・外注先 技術指導者
B20: 委託・外注又は指導等の詳細
B21: 契約予定期間 | P21: 令和 年 月 ～ 令和 年 月
B22: 選定理由
B23: 上記委託先は、自社と資本関係、役員または従業員の兼務、自社の代表者３親等以内の親族による経営ではない。 | BF23: 選択してください

Sheet 設備
B1: 【設備等導入費】
C2: <留意事項>
B3: ・１契約あたり30万円以上の項目は、申請時に見積書・カタログ等の提出が必要です。 | C3: ・１契約30万円以上の項目は、見積書・カタログ等の提出が必要です。
B4: ・１契約あたり100万円以上の項目は、相見積の結果を「相見積」シートに記載してください。 | C4: ・１契約100万円以上の項目は、相見積の結果を「相見積」シートに記載してください。
B5: ・１品あたりの金額(単価)が税抜10万円未満の経費は、申請できません。
AM7: 【税抜】 | AS7: 【税抜】 | AY7: 【税込】 | BM7: （単位：円）
B8: 支出 | F8: 製品名 又は | P8: 用途 | AD8: 調達 | AG8: 数量 | AM8: 単価 | AS8: 助成対象経費 | AY8: 助成事業に | BE8: ＜留意事項＞
B9: 番号 | F9: 施工内容 | P9: (取組に必要な理由) | AD9: 内容 | AG9: (A) | AM9: (B) | AS9: （A）×(B) | AY9: 要する経費 | BE9: 見積書 | BH9: 相見積 | BK9: 単価
B10: 設-1 | F10: 写真暗室専用シンク | P10: 様々な技法に沿った温度管理や薬品使用に特化した暗室作業専用シンク | AD10: (選択) | AG10: 1 | AM10: 1832000 | AS10: =IF(AM10="","",AG10*AM10) -> 1832000 | AY10: =IF(AM10="","",ROUNDDOWN(AG10*AM10*1.1,0)) -> 2015200 | BE10: =IF(AS10="","",IF(AS10>=300000,"必要","")) -> 必要 | BH10: =IF(AS10="","",IF(AS10>=1000000,"必要","")) -> 必要 | BK10: =IF(AM10="","",IF(AM10<100000,"×","〇")) -> 〇
B11: 設-2 | AD11: (選択) | AS11: =IF(AM11="","",AG11*AM11) | AY11: =IF(AM11="","",ROUNDDOWN(AG11*AM11*1.1,0)) | BE11: =IF(AS11="","",IF(AS11>=300000,"必要","")) | BH11: =IF(AS11="","",IF(AS11>=1000000,"必要","")) | BK11: =IF(AM11="","",IF(AM11<100000,"×","〇"))
B12: 設-3 | AD12: (選択) | AS12: =IF(AM12="","",AG12*AM12) | AY12: =IF(AM12="","",ROUNDDOWN(AG12*AM12*1.1,0)) | BE12: =IF(AS12="","",IF(AS12>=300000,"必要","")) | BH12: =IF(AS12="","",IF(AS12>=1000000,"必要","")) | BK12: =IF(AM12="","",IF(AM12<100000,"×","〇"))
B13: 設-4 | AD13: (選択) | AS13: =IF(AM13="","",AG13*AM13) | AY13: =IF(AM13="","",ROUNDDOWN(AG13*AM13*1.1,0)) | BE13: =IF(AS13="","",IF(AS13>=300000,"必要","")) | BH13: =IF(AS13="","",IF(AS13>=1000000,"必要","")) | BK13: =IF(AM13="","",IF(AM13<100000,"×","〇"))
B14: 設-5 | AD14: (選択) | AS14: =IF(AM14="","",AG14*AM14) | AY14: =IF(AM14="","",ROUNDDOWN(AG14*AM14*1.1,0)) | BE14: =IF(AS14="","",IF(AS14>=300000,"必要","")) | BH14: =IF(AS14="","",IF(AS14>=1000000,"必要","")) | BK14: =IF(AM14="","",IF(AM14<100000,"×","〇"))
B15: 設-6 | AD15: (選択) | AS15: =IF(AM15="","",AG15*AM15) | AY15: =IF(AM15="","",ROUNDDOWN(AG15*AM15*1.1,0)) | BE15: =IF(AS15="","",IF(AS15>=300000,"必要","")) | BH15: =IF(AS15="","",IF(AS15>=1000000,"必要","")) | BK15: =IF(AM15="","",IF(AM15<100000,"×","〇"))
B16: 設-7 | AD16: (選択) | AS16: =IF(AM16="","",AG16*AM16) | AY16: =IF(AM16="","",ROUNDDOWN(AG16*AM16*1.1,0)) | BE16: =IF(AS16="","",IF(AS16>=300000,"必要","")) | BH16: =IF(AS16="","",IF(AS16>=1000000,"必要","")) | BK16: =IF(AM16="","",IF(AM16<100000,"×","〇"))
B17: 設-8 | AD17: (選択) | AS17: =IF(AM17="","",AG17*AM17) | AY17: =IF(AM17="","",ROUNDDOWN(AG17*AM17*1.1,0)) | BE17: =IF(AS17="","",IF(AS17>=300000,"必要","")) | BH17: =IF(AS17="","",IF(AS17>=1000000,"必要","")) | BK17: =IF(AM17="","",IF(AM17<100000,"×","〇"))
B18: 設-9 | AD18: (選択) | AS18: =IF(AM18="","",AG18*AM18) | AY18: =IF(AM18="","",ROUNDDOWN(AG18*AM18*1.1,0)) | BE18: =IF(AS18="","",IF(AS18>=300000,"必要","")) | BH18: =IF(AS18="","",IF(AS18>=1000000,"必要","")) | BK18: =IF(AM18="","",IF(AM18<100000,"×","〇"))
B19: 設-10 | AD19: (選択) | AS19: =IF(AM19="","",AG19*AM19) | AY19: =IF(AM19="","",ROUNDDOWN(AG19*AM19*1.1,0)) | BE19: =IF(AS19="","",IF(AS19>=300000,"必要","")) | BH19: =IF(AS19="","",IF(AS19>=1000000,"必要","")) | BK19: =IF(AM19="","",IF(AM19<100000,"×","〇"))
AM20: 合計 | AS20: =SUM(AS10:AX19) -> 1832000 | AY20: =SUM(AY10:BD19) -> 2015200

Sheet システム
B1: 【システム等導入費】
C2: <留意事項>
B3: ・１契約あたり30万円以上の項目は、申請時に見積書・カタログ等の提出が必要です。 | C3: ・１契約30万円以上の項目は、見積書・カタログ等の提出が必要です。
B4: ・１契約あたり100万円以上の項目は、相見積の結果を「相見積」シートに記載してください。 | C4: ・１契約100万円以上の項目は、相見積の結果を「相見積」シートに記載してください。
B5: ・１品あたりの金額(単価)が税抜10万円未満の経費は、申請できません。
C6: ※調達方法がリースの場合、(A)に月数、(B)に月額料金を記入してください。
AM8: 【税抜】 | AS8: 【税抜】 | AY8: 【税込】 | BM8: （単位：円）
B9: 支出 | F9: 品名 | P9: 用途 | AD9: 調達 | AG9: 数量 | AM9: 単価 | AS9: 助成対象経費 | AY9: 助成事業に | BE9: ＜留意事項＞
B10: 番号 | P10: (取組に必要な理由) | AD10: 内容 | AG10: (A) | AM10: (B) | AS10: （A）×(B) | AY10: 要する経費 | BE10: 見積書 | BH10: 相見積 | BK10: 単価
B11: シ-1 | AD11: (選択) | AS11: =IF(AM11="","",AG11*AM11) | AY11: =IF(AM11="","",ROUNDDOWN(AG11*AM11*1.1,0)) | BE11: =IF(AS11="","",IF(AS11>=300000,"必要","")) | BH11: =IF(AS11="","",IF(AS11>=1000000,"必要","")) | BK11: =IF(AM11="","",IF(AM11<100000,"×","〇"))
B12: シ-2 | AD12: (選択) | AS12: =IF(AM12="","",AG12*AM12) | AY12: =IF(AM12="","",ROUNDDOWN(AG12*AM12*1.1,0)) | BE12: =IF(AS12="","",IF(AS12>=300000,"必要","")) | BH12: =IF(AS12="","",IF(AS12>=1000000,"必要","")) | BK12: =IF(AM12="","",IF(AM12<100000,"×","〇"))
B13: シ-3 | AD13: (選択) | AS13: =IF(AM13="","",AG13*AM13) | AY13: =IF(AM13="","",ROUNDDOWN(AG13*AM13*1.1,0)) | BE13: =IF(AS13="","",IF(AS13>=300000,"必要","")) | BH13: =IF(AS13="","",IF(AS13>=1000000,"必要","")) | BK13: =IF(AM13="","",IF(AM13<100000,"×","〇"))
B14: シ-4 | AD14: (選択) | AS14: =IF(AM14="","",AG14*AM14) | AY14: =IF(AM14="","",ROUNDDOWN(AG14*AM14*1.1,0)) | BE14: =IF(AS14="","",IF(AS14>=300000,"必要","")) | BH14: =IF(AS14="","",IF(AS14>=1000000,"必要","")) | BK14: =IF(AM14="","",IF(AM14<100000,"×","〇"))
B15: シ-5 | AD15: (選択) | AS15: =IF(AM15="","",AG15*AM15) | AY15: =IF(AM15="","",ROUNDDOWN(AG15*AM15*1.1,0)) | BE15: =IF(AS15="","",IF(AS15>=300000,"必要","")) | BH15: =IF(AS15="","",IF(AS15>=1000000,"必要","")) | BK15: =IF(AM15="","",IF(AM15<100000,"×","〇"))
B16: シ-6 | AD16: (選択) | AS16: =IF(AM16="","",AG16*AM16) | AY16: =IF(AM16="","",ROUNDDOWN(AG16*AM16*1.1,0)) | BE16: =IF(AS16="","",IF(AS16>=300000,"必要","")) | BH16: =IF(AS16="","",IF(AS16>=1000000,"必要","")) | BK16: =IF(AM16="","",IF(AM16<100000,"×","〇"))
B17: シ-7 | AD17: (選択) | AS17: =IF(AM17="","",AG17*AM17) | AY17: =IF(AM17="","",ROUNDDOWN(AG17*AM17*1.1,0)) | BE17: =IF(AS17="","",IF(AS17>=300000,"必要","")) | BH17: =IF(AS17="","",IF(AS17>=1000000,"必要","")) | BK17: =IF(AM17="","",IF(AM17<100000,"×","〇"))
B18: シ-8 | AD18: (選択) | AS18: =IF(AM18="","",AG18*AM18) | AY18: =IF(AM18="","",ROUNDDOWN(AG18*AM18*1.1,0)) | BE18: =IF(AS18="","",IF(AS18>=300000,"必要","")) | BH18: =IF(AS18="","",IF(AS18>=1000000,"必要","")) | BK18: =IF(AM18="","",IF(AM18<100000,"×","〇"))
B19: シ-9 | AD19: (選択) | AS19: =IF(AM19="","",AG19*AM19) | AY19: =IF(AM19="","",ROUNDDOWN(AG19*AM19*1.1,0)) | BE19: =IF(AS19="","",IF(AS19>=300000,"必要","")) | BH19: =IF(AS19="","",IF(AS19>=1000000,"必要","")) | BK19: =IF(AM19="","",IF(AM19<100000,"×","〇"))
B20: シ-10 | AD20: (選択) | AS20: =IF(AM20="","",AG20*AM20) | AY20: =IF(AM20="","",ROUNDDOWN(AG20*AM20*1.1,0)) | BE20: =IF(AS20="","",IF(AS20>=300000,"必要","")) | BH20: =IF(AS20="","",IF(AS20>=1000000,"必要","")) | BK20: =IF(AM20="","",IF(AM20<100000,"×","〇"))
AM21: 合計 | AS21: =SUM(AS11:AX20) -> 0 | AY21: =SUM(AY11:BD20) -> 0
B23: ＜システム等導入計画書＞
C24: ・計上した全ての契約先について記載してください。
C25: ・表が足りない場合は、印刷範囲を広げて使用欄を増やしてください。
B26: 支出番号 | K26: 品名 | AL26: 契約先企業名
B27: 依頼内容
B28: 契約予定期間 | P28: 令和 年 月 ～ 令和 年 月
B29: 選定理由
B30: 上記購入先は、自社と資本関係、役員または従業員の兼務、自社の代表者３親等以内の親族による経営ではない。 | BF30: 選択してください

Sheet 専門
B1: 【専門家指導費】
C2: <留意事項>
B3: ・１契約あたり30万円以上の項目は、申請時に見積書・カタログ等の提出が必要です。 | C3: ・１契約30万円以上の項目は、見積書・カタログ等の提出が必要です。
B4: ・１契約あたり100万円以上の項目は、相見積の結果を「相見積」シートに記載してください。 | C4: ・１契約100万円以上の項目は、相見積の結果を「相見積」シートに記載してください。
AM7: 【税抜】 | AS7: 【税抜】 | AY7: 【税込】 | BM7: （単位：円）
B8: 支出 | F8: 品名 | P8: 用途 | AG8: 指導日数 | AM8: 単価 | AS8: 助成対象経費 | AY8: 助成事業に | BE8: ＜留意事項＞
B9: 番号 | P9: (取組に必要な理由) | AG9: (A) | AM9: (B) | AS9: （A）×(B) | AY9: 要する経費 | BE9: 見積書 | BH9: 相見積 | BK9: 単価
B10: 専-1 | F10: 猪股良文 | P10: 暗室制作に関する助言およびワークショッププログラムの事前テストおよびカリキュラム作成 | AD10: (選択) | AG10: 100 | AM10: 15000 | AS10: =IF(AM10="","",AG10*AM10) -> 1500000 | AY10: =IF(AM10="","",ROUNDDOWN(AG10*AM10*1.1,0)) -> 1650000 | BE10: =IF(AS10="","",IF(AS10>=300000,"必要","")) -> 必要 | BH10: =IF(AS10="","",IF(AS10>=1000000,"必要","")) -> 必要 | BK10: =IF(AM10="","",IF(AM10<100000,"×","〇")) -> ×
B11: 専-2 | AD11: (選択) | AS11: =IF(AM11="","",AG11*AM11) | AY11: =IF(AM11="","",ROUNDDOWN(AG11*AM11*1.1,0)) | BE11: =IF(AS11="","",IF(AS11>=300000,"必要","")) | BH11: =IF(AS11="","",IF(AS11>=1000000,"必要","")) | BK11: =IF(AM11="","",IF(AM11<100000,"×","〇"))
B12: 専-3 | AD12: (選択) | AS12: =IF(AM12="","",AG12*AM12) | AY12: =IF(AM12="","",ROUNDDOWN(AG12*AM12*1.1,0)) | BE12: =IF(AS12="","",IF(AS12>=300000,"必要","")) | BH12: =IF(AS12="","",IF(AS12>=1000000,"必要","")) | BK12: =IF(AM12="","",IF(AM12<100000,"×","〇"))
B13: 専-4 | AD13: (選択) | AS13: =IF(AM13="","",AG13*AM13) | AY13: =IF(AM13="","",ROUNDDOWN(AG13*AM13*1.1,0)) | BE13: =IF(AS13="","",IF(AS13>=300000,"必要","")) | BH13: =IF(AS13="","",IF(AS13>=1000000,"必要","")) | BK13: =IF(AM13="","",IF(AM13<100000,"×","〇"))
B14: 専-5 | AD14: (選択) | AS14: =IF(AM14="","",AG14*AM14) | AY14: =IF(AM14="","",ROUNDDOWN(AG14*AM14*1.1,0)) | BE14: =IF(AS14="","",IF(AS14>=300000,"必要","")) | BH14: =IF(AS14="","",IF(AS14>=1000000,"必要","")) | BK14: =IF(AM14="","",IF(AM14<100000,"×","〇"))
AM15: 合計 | AS15: =SUM(AS10:AX14) -> 1500000 | AY15: =SUM(AY10:BD14) -> 1650000
B16: ＜専門家指導の計画書＞
B17: ・計上した全ての専門家について記載してください。表が足りない場合、印刷範囲を広げて使用欄を増やしてください。
B18: 支出番号 | F18: 専-1 | K18: 専門家名 | P18: 猪股良文
B19: 経歴・実績 | P19: アマナサルト（株式会社アマナ運営の世界最大級プラチナプリント工房）にてオルタナティブ・プリント制作担当後、アトリエ・シャテーニュにてオルタナティブプロセス・ワークショップを9年間担当
B20: 指導内容 | P20: 暗室制作における助言および、ワークショップ技術のレクチャーおよび事前テスト・カリキュラム作成
B21: 契約予定期間 | P21: 令和 8 年 5 月 ～ 令和 8 年 8 月
B22: 上記指導先は、自社と資本関係、役員または従業員の兼務、自社の代表者３親等以内の親族による経営ではない。 | BF22: 関連なし

Sheet 賃借
B1: 【不動産賃借料】
C2: <留意事項>
C3: ・１契約30万円以上の項目は、見積書・カタログ等の提出が必要です。
C4: ・１契約100万円以上の項目は、相見積の結果を「相見積」シートに記載してください。
AM7: 【税抜】 | AS7: 【税抜】 | AY7: 【税込】 | BM7: （単位：円）
B8: 支出 | F8: 施設名称 | P8: 用途 | AD8: 調達 | AG8: 賃借月数 | AM8: 月額賃料 | AS8: 助成対象経費 | AY8: 助成事業に | BE8: ＜留意事項＞
B9: 番号 | P9: (取組に必要な理由) | AD9: 方法 | AG9: (A) | AM9: (B) | AS9: （A）×(B) | AY9: 要する経費 | BE9: 見積書 | BH9: 相見積 | BK9: 単価
B10: 賃-1 | F10: MT-O中野新橋 102号室 | P10: ワークショップスペースおよびレンタル暗室制作 | AD10: (選択) | AG10: 12 | AM10: 318000 | AS10: =IF(AM10="","",AG10*AM10) -> 3816000 | AY10: =IF(AM10="","",ROUNDDOWN(AG10*AM10*1.1,0)) -> 4197600 | BE10: =IF(AS10="","",IF(AS10>=300000,"必要","")) -> 必要 | BH10: =IF(AS10="","",IF(AS10>=1000000,"必要","")) -> 必要 | BK10: =IF(AM10="","",IF(AM10<100000,"×","〇")) -> 〇
B11: 賃-2 | AD11: (選択) | AS11: =IF(AM11="","",AG11*AM11) | AY11: =IF(AM11="","",ROUNDDOWN(AG11*AM11*1.1,0)) | BE11: =IF(AS11="","",IF(AS11>=300000,"必要","")) | BH11: =IF(AS11="","",IF(AS11>=1000000,"必要","")) | BK11: =IF(AM11="","",IF(AM11<100000,"×","〇"))
B12: 賃-3 | AD12: (選択) | AS12: =IF(AM12="","",AG12*AM12) | AY12: =IF(AM12="","",ROUNDDOWN(AG12*AM12*1.1,0)) | BE12: =IF(AS12="","",IF(AS12>=300000,"必要","")) | BH12: =IF(AS12="","",IF(AS12>=1000000,"必要","")) | BK12: =IF(AM12="","",IF(AM12<100000,"×","〇"))
B13: 賃-4 | AD13: (選択) | AS13: =IF(AM13="","",AG13*AM13) | AY13: =IF(AM13="","",ROUNDDOWN(AG13*AM13*1.1,0)) | BE13: =IF(AS13="","",IF(AS13>=300000,"必要","")) | BH13: =IF(AS13="","",IF(AS13>=1000000,"必要","")) | BK13: =IF(AM13="","",IF(AM13<100000,"×","〇"))
B14: 賃-5 | AD14: (選択) | AS14: =IF(AM14="","",AG14*AM14) | AY14: =IF(AM14="","",ROUNDDOWN(AG14*AM14*1.1,0)) | BE14: =IF(AS14="","",IF(AS14>=300000,"必要","")) | BH14: =IF(AS14="","",IF(AS14>=1000000,"必要","")) | BK14: =IF(AM14="","",IF(AM14<100000,"×","〇"))
AM15: 合計 | AS15: =SUM(AS10:AX14) -> 3816000 | AY15: =SUM(AY10:BD14) -> 4197600
B16: ＜賃借計画書＞
B17: ・計上した全ての項目について記載してください。表が足りない場合、印刷範囲を広げて使用欄を増やしてください。
B18: 支出番号 | F18: 賃-1 | K18: 契約予定先 | P18: 株式会社ハイプロファイル
B19: 賃借施設等 | I19: 名称 | P19: MT-O中野新橋 102号室
I20: 所在地 | P20: 東京都中野区本町5-6-6
I21: 延床面積(㎡) | P21: 60.32㎡
B22: 契約予定期間 | P22: 令和 年 月 ～ 令和 年 月
B23: 選定理由 | P23: 近隣に東京工芸大学があり、学生の利用者獲得を目指し、卒業後も含めた長期利用者獲得が見込めるから
B24: 上記賃借について、親会社、子会社、グループ企業等関連企業との関連 | BC24: 関連なし

Sheet 販売
B1: 【販売促進費】
C2: <留意事項>
B3: ・１契約あたり30万円以上の項目は、申請時に見積書・カタログ等の提出が必要です。 | C3: ・１契約30万円以上の項目は、見積書・カタログ等の提出が必要です。
B4: ・１契約あたり100万円以上の項目は、相見積の結果を「相見積」シートに記載してください。 | C4: ・１契約100万円以上の項目は、相見積の結果を「相見積」シートに記載してください。
AM7: 【税抜】 | AS7: 【税抜】 | AY7: 【税込】 | BM7: （単位：円）
B8: 支出 | F8: 品名 | P8: 用途 | AD8: 調達 | AG8: 数量 | AM8: 単価 | AS8: 助成対象経費 | AY8: 助成事業に | BE8: ＜留意事項＞
B9: 番号 | P9: (取組に必要な理由) | AD9: 方法 | AG9: (A) | AM9: (B) | AS9: （A）×(B) | AY9: 要する経費 | BE9: 見積書 | BH9: 相見積 | BK9: 単価
B10: 販-1 | F10: 雑誌『写真』-Vol.9広告出稿 | AD10: (選択) | AG10: 1 | AM10: 160000 | AS10: =IF(AM10="","",AG10*AM10) -> 160000 | AY10: =IF(AM10="","",ROUNDDOWN(AG10*AM10*1.1,0)) -> 176000 | BE10: =IF(AS10="","",IF(AS10>=300000,"必要","")) | BH10: =IF(AS10="","",IF(AS10>=1000000,"必要","")) | BK10: =IF(AM10="","",IF(AM10<100000,"×","〇")) -> 〇
B11: 販-2 | F11: 雑誌『写真』-Vol.10広告出稿 | AD11: (選択) | AG11: 1 | AM11: 160000 | AS11: =IF(AM11="","",AG11*AM11) -> 160000 | AY11: =IF(AM11="","",ROUNDDOWN(AG11*AM11*1.1,0)) -> 176000 | BE11: =IF(AS11="","",IF(AS11>=300000,"必要","")) | BH11: =IF(AS11="","",IF(AS11>=1000000,"必要","")) | BK11: =IF(AM11="","",IF(AM11<100000,"×","〇")) -> 〇
B12: 販-3 | AD12: (選択) | AS12: =IF(AM12="","",AG12*AM12) | AY12: =IF(AM12="","",ROUNDDOWN(AG12*AM12*1.1,0)) | BE12: =IF(AS12="","",IF(AS12>=300000,"必要","")) | BH12: =IF(AS12="","",IF(AS12>=1000000,"必要","")) | BK12: =IF(AM12="","",IF(AM12<100000,"×","〇"))
B13: 販-4 | AD13: (選択) | AS13: =IF(AM13="","",AG13*AM13) | AY13: =IF(AM13="","",ROUNDDOWN(AG13*AM13*1.1,0)) | BE13: =IF(AS13="","",IF(AS13>=300000,"必要","")) | BH13: =IF(AS13="","",IF(AS13>=1000000,"必要","")) | BK13: =IF(AM13="","",IF(AM13<100000,"×","〇"))
B14: 販-5 | AD14: (選択) | AS14: =IF(AM14="","",AG14*AM14) | AY14: =IF(AM14="","",ROUNDDOWN(AG14*AM14*1.1,0)) | BE14: =IF(AS14="","",IF(AS14>=300000,"必要","")) | BH14: =IF(AS14="","",IF(AS14>=1000000,"必要","")) | BK14: =IF(AM14="","",IF(AM14<100000,"×","〇"))
B15: 販-6 | AD15: (選択) | AS15: =IF(AM15="","",AG15*AM15) | AY15: =IF(AM15="","",ROUNDDOWN(AG15*AM15*1.1,0)) | BE15: =IF(AS15="","",IF(AS15>=300000,"必要","")) | BH15: =IF(AS15="","",IF(AS15>=1000000,"必要","")) | BK15: =IF(AM15="","",IF(AM15<100000,"×","〇"))
B16: 販-7 | AD16: (選択) | AS16: =IF(AM16="","",AG16*AM16) | AY16: =IF(AM16="","",ROUNDDOWN(AG16*AM16*1.1,0)) | BE16: =IF(AS16="","",IF(AS16>=300000,"必要","")) | BH16: =IF(AS16="","",IF(AS16>=1000000,"必要","")) | BK16: =IF(AM16="","",IF(AM16<100000,"×","〇"))
B17: 販-8 | AD17: (選択) | AS17: =IF(AM17="","",AG17*AM17) | AY17: =IF(AM17="","",ROUNDDOWN(AG17*AM17*1.1,0)) | BE17: =IF(AS17="","",IF(AS17>=300000,"必要","")) | BH17: =IF(AS17="","",IF(AS17>=1000000,"必要","")) | BK17: =IF(AM17="","",IF(AM17<100000,"×","〇"))
B18: 販-9 | AD18: (選択) | AS18: =IF(AM18="","",AG18*AM18) | AY18: =IF(AM18="","",ROUNDDOWN(AG18*AM18*1.1,0)) | BE18: =IF(AS18="","",IF(AS18>=300000,"必要","")) | BH18: =IF(AS18="","",IF(AS18>=1000000,"必要","")) | BK18: =IF(AM18="","",IF(AM18<100000,"×","〇"))
B19: 販-10 | AD19: (選択) | AS19: =IF(AM19="","",AG19*AM19) | AY19: =IF(AM19="","",ROUNDDOWN(AG19*AM19*1.1,0)) | BE19: =IF(AS19="","",IF(AS19>=300000,"必要","")) | BH19: =IF(AS19="","",IF(AS19>=1000000,"必要","")) | BK19: =IF(AM19="","",IF(AM19<100000,"×","〇"))
AM20: 合計 | AS20: =SUM(AS10:AX19) -> 320000 | AY20: =SUM(AY10:BD19) -> 352000
B22: 【展示会に出展する場合】
B23: 支出番号 | K23: 展示会名 | AL23: 主催(契約先)
B24: 会期 | P24: 令和 年 月 日 ～ 令和 年 月 日
B25: 会場
B26: PR内容(商品名)
B28: 【ECサイトに出店する場合】
B29: 支出番号 | K29: ECモール名 | AL29: 契約先
B30: 出店予定時期 | P30: 令和 年 月
B31: 出店内容(商品名)

Sheet 他
B1: 【その他経費】
C2: <留意事項>
B3: ・１契約あたり30万円以上の項目は、申請時に見積書・カタログ等の提出が必要です。 | C3: ・１契約あたり30万円以上の項目は、申請時に見積書・カタログ等の提出が必要です。
B4: ・１契約あたり100万円以上の項目は、相見積の結果を「相見積」シートに記載してください。 | C4: ・１契約100万円以上の項目は、相見積の結果を「相見積」シートに記載してください。
B5: ・１品あたりの金額(単価)が税抜10万円未満の経費は、申請できません。
AM7: 【税抜】 | AS7: 【税抜】 | AY7: 【税込】 | BM7: （単位：円）
B8: 支出 | F8: 品名 | P8: 用途 | AD8: 調達 | AG8: 数量 | AM8: 単価 | AS8: 助成対象経費 | AY8: 助成事業に | BE8: ＜留意事項＞
B9: 番号 | P9: (取組に必要な理由) | AD9: 方法 | AG9: (A) | AM9: (B) | AS9: （A）×(B) | AY9: 要する経費 | BE9: 見積書 | BH9: 相見積 | BK9: 単価
B10: 他-1 | AD10: (選択) | AS10: =IF(AM10="","",AG10*AM10) | AY10: =IF(AM10="","",ROUNDDOWN(AG10*AM10*1.1,0)) | BE10: =IF(AS10="","",IF(AS10>=300000,"必要","")) | BH10: =IF(AS10="","",IF(AS10>=1000000,"必要","")) | BK10: =IF(AM10="","",IF(AM10<100000,"×","〇"))
B11: 他-2 | AD11: (選択) | AS11: =IF(AM11="","",AG11*AM11) | AY11: =IF(AM11="","",ROUNDDOWN(AG11*AM11*1.1,0)) | BE11: =IF(AS11="","",IF(AS11>=300000,"必要","")) | BH11: =IF(AS11="","",IF(AS11>=1000000,"必要","")) | BK11: =IF(AM11="","",IF(AM11<100000,"×","〇"))
B12: 他-3 | AD12: (選択) | AS12: =IF(AM12="","",AG12*AM12) | AY12: =IF(AM12="","",ROUNDDOWN(AG12*AM12*1.1,0)) | BE12: =IF(AS12="","",IF(AS12>=300000,"必要","")) | BH12: =IF(AS12="","",IF(AS12>=1000000,"必要","")) | BK12: =IF(AM12="","",IF(AM12<100000,"×","〇"))
B13: 他-4 | AD13: (選択) | AS13: =IF(AM13="","",AG13*AM13) | AY13: =IF(AM13="","",ROUNDDOWN(AG13*AM13*1.1,0)) | BE13: =IF(AS13="","",IF(AS13>=300000,"必要","")) | BH13: =IF(AS13="","",IF(AS13>=1000000,"必要","")) | BK13: =IF(AM13="","",IF(AM13<100000,"×","〇"))
B14: 他-5 | AD14: (選択) | AS14: =IF(AM14="","",AG14*AM14) | AY14: =IF(AM14="","",ROUNDDOWN(AG14*AM14*1.1,0)) | BE14: =IF(AS14="","",IF(AS14>=300000,"必要","")) | BH14: =IF(AS14="","",IF(AS14>=1000000,"必要","")) | BK14: =IF(AM14="","",IF(AM14<100000,"×","〇"))
B15: 他-6 | AD15: (選択) | AS15: =IF(AM15="","",AG15*AM15) | AY15: =IF(AM15="","",ROUNDDOWN(AG15*AM15*1.1,0)) | BE15: =IF(AS15="","",IF(AS15>=300000,"必要","")) | BH15: =IF(AS15="","",IF(AS15>=1000000,"必要","")) | BK15: =IF(AM15="","",IF(AM15<100000,"×","〇"))
B16: 他-7 | AD16: (選択) | AS16: =IF(AM16="","",AG16*AM16) | AY16: =IF(AM16="","",ROUNDDOWN(AG16*AM16*1.1,0)) | BE16: =IF(AS16="","",IF(AS16>=300000,"必要","")) | BH16: =IF(AS16="","",IF(AS16>=1000000,"必要","")) | BK16: =IF(AM16="","",IF(AM16<100000,"×","〇"))
B17: 他-8 | AD17: (選択) | AS17: =IF(AM17="","",AG17*AM17) | AY17: =IF(AM17="","",ROUNDDOWN(AG17*AM17*1.1,0)) | BE17: =IF(AS17="","",IF(AS17>=300000,"必要","")) | BH17: =IF(AS17="","",IF(AS17>=1000000,"必要","")) | BK17: =IF(AM17="","",IF(AM17<100000,"×","〇"))
B18: 他-9 | AD18: (選択) | AS18: =IF(AM18="","",AG18*AM18) | AY18: =IF(AM18="","",ROUNDDOWN(AG18*AM18*1.1,0)) | BE18: =IF(AS18="","",IF(AS18>=300000,"必要","")) | BH18: =IF(AS18="","",IF(AS18>=1000000,"必要","")) | BK18: =IF(AM18="","",IF(AM18<100000,"×","〇"))
B19: 他-10 | AD19: (選択) | AS19: =IF(AM19="","",AG19*AM19) | AY19: =IF(AM19="","",ROUNDDOWN(AG19*AM19*1.1,0)) | BE19: =IF(AS19="","",IF(AS19>=300000,"必要","")) | BH19: =IF(AS19="","",IF(AS19>=1000000,"必要","")) | BK19: =IF(AM19="","",IF(AM19<100000,"×","〇"))
AM20: 合計 | AS20: =SUM(AS10:AX19) -> 0 | AY20: =SUM(AY10:BD19) -> 0
B22: ＜履行を確認するための書類＞
B23: 支出番号 | F23: 購入品等の現物の有無 | P23: 履行確認書類
B24: 他-1 | F24: (選択) | P24: =IF(F24="(選択)","",IF(F24="有","カラー写真２～３枚(現物の個数、設置場所等が複数の画角から確認できるもの","履行完了届や報告書など、購入等先が発行する契約の履行を証明する書類"))
B25: 他-2 | F25: (選択) | P25: =IF(F25="(選択)","",IF(F25="有","カラー写真２～３枚(現物の個数、設置場所等が複数の画角から確認できるもの","履行完了届や報告書など、購入等先が発行する契約の履行を証明する書類"))
B26: 他-3 | F26: (選択) | P26: =IF(F26="(選択)","",IF(F26="有","カラー写真２～３枚(現物の個数、設置場所等が複数の画角から確認できるもの","履行完了届や報告書など、購入等先が発行する契約の履行を証明する書類"))
B27: 他-4 | F27: (選択) | P27: =IF(F27="(選択)","",IF(F27="有","カラー写真２～３枚(現物の個数、設置場所等が複数の画角から確認できるもの","履行完了届や報告書など、購入等先が発行する契約の履行を証明する書類"))
B28: 他-5 | F28: (選択) | P28: =IF(F28="(選択)","",IF(F28="有","カラー写真２～３枚(現物の個数、設置場所等が複数の画角から確認できるもの","履行完了届や報告書など、購入等先が発行する契約の履行を証明する書類"))
B29: 他-6 | F29: (選択) | P29: =IF(F29="(選択)","",IF(F29="有","カラー写真２～３枚(現物の個数、設置場所等が複数の画角から確認できるもの","履行完了届や報告書など、購入等先が発行する契約の履行を証明する書類"))
B30: 他-7 | F30: (選択) | P30: =IF(F30="(選択)","",IF(F30="有","カラー写真２～３枚(現物の個数、設置場所等が複数の画角から確認できるもの","履行完了届や報告書など、購入等先が発行する契約の履行を証明する書類"))
B31: 他-8 | F31: (選択) | P31: =IF(F31="(選択)","",IF(F31="有","カラー写真２～３枚(現物の個数、設置場所等が複数の画角から確認できるもの","履行完了届や報告書など、購入等先が発行する契約の履行を証明する書類"))
B32: 他-9 | F32: (選択) | P32: =IF(F32="(選択)","",IF(F32="有","カラー写真２～３枚(現物の個数、設置場所等が複数の画角から確認できるもの","履行完了届や報告書など、購入等先が発行する契約の履行を証明する書類"))
B33: 他-10 | F33: (選択) | P33: =IF(F33="(選択)","",IF(F33="有","カラー写真２～３枚(現物の個数、設置場所等が複数の画角から確認できるもの","履行完了届や報告書など、購入等先が発行する契約の履行を証明する書類"))

Sheet 相見積一覧
B1: 相見積一覧（及び見積限定理由書）
C2: ・１契約100万円以上の項目について、相見積の結果を記入してください。
C3: ・見積を１社からしか取らなかった場合は、その理由を「見積限定理由」に記入してください。
B6: 支出 | F6: 見積金額（単位：円） | AF6: 見積限定理由
B7: 番号 | F7: １社目 | S7: ２社目 | AF7: （１社からのみ見積を取った場合に、その理由を記入）
B8: 設-1 | F8: 1832000 | AF8: 写真暗室専用の塩ビシンクの制作実績がある唯一の会社（有限会社豊川写真事務所）であるから
B9: 賃-1 | F9: 318000 | AF9: 2025年12月31日現在、理想とする立地条件に沿った空室物件がここ以外に見つからないため。

Sheet 資金
A1: ３．当事業の資金計画 | BA1: 助成率
B2: 助成対象期間の全体経費を記入してください。 | Z2: 申請者区分 | AF2: =IF(OR(表紙!J8="",表紙!J8="(選択)"),"",表紙!J8) -> A: 中小企業者(賃上げなし) | AZ2: A: 中小企業者(賃上げなし) | BA2: 0.66666667
Z3: 助成率 | AF3: =IF(AF2="","",VLOOKUP(AF2,$AZ$1:$BA$4,2,FALSE)) -> 0.66666667 | AZ3: B: 賃金引上げ計画を掲げる中小企業者 | BA3: 0.75
A4: （１）経費区分別内訳 | AN4: （単位：円） | AZ4: C: 賃金引上げ計画を掲げる小規模企業者 | BA4: 0.8
A5: 経 費 区 分 | P5: 助成事業に要する経費 | Z5: 助 成 対 象 経 費 | AJ5: 助成金交付申請額
P6: （税込） | Z6: （税抜） | AJ6: （千円未満切捨）
A7: 内 訳 | C7: 原材料・副資材費 | P7: =IF(原材料!AY65=0,"",原材料!AY65) -> 2058963 | Z7: =IF(原材料!AS65=0,"",原材料!AS65) -> 1871785 | AJ7: =IFERROR(IF(Z7="","",IF(ROUNDDOWN(Z7*$AF$3,-3)>=8000000,8000000,ROUNDDOWN(Z7*$AF$3,-3))),"") -> 1247000
C8: 機械装置・工具器具費 | P8: =IF(機械!AY16=0,"",機械!AY16) -> 1298000 | Z8: =IF(機械!AS16=0,"",機械!AS16) -> 1180000 | AJ8: =IFERROR(IF(Z8="","",IF(ROUNDDOWN(Z8*$AF$3,-3)>=8000000,8000000,ROUNDDOWN(Z8*$AF$3,-3))),"") -> 786000
C9: 委託・外注費 | P9: =IF(委託!AY15=0,"",委託!AY15) | Z9: =IF(委託!AS15=0,"",委託!AS15) | AJ9: =IFERROR(IF(Z9="","",IF(ROUNDDOWN(Z9*$AF$3,-3)>=8000000,8000000,ROUNDDOWN(Z9*$AF$3,-3))),"")
C10: 産業財産権出願・導入費 | P10: =IF(財産権!AY15=0,"",財産権!AY15) | Z10: =IF(財産権!AS15=0,"",財産権!AS15) | AJ10: =IFERROR(IF(Z10="","",IF(ROUNDDOWN(Z10*$AF$3,-3)>=8000000,8000000,ROUNDDOWN(Z10*$AF$3,-3))),"")
C11: 規格等認証・登録費 | P11: =IF(規格!AY15=0,"",規格!AY15) | Z11: =IF(規格!AS15=0,"",規格!AS15) | AJ11: =IFERROR(IF(Z11="","",IF(ROUNDDOWN(Z11*$AF$3,-3)>=8000000,8000000,ROUNDDOWN(Z11*$AF$3,-3))),"")
C12: 設備等導入費 | P12: =IF(設備!AY20=0,"",設備!AY20) -> 2015200 | Z12: =IF(設備!AS20=0,"",設備!AS20) -> 1832000 | AJ12: =IFERROR(IF(Z12="","",IF(ROUNDDOWN(Z12*$AF$3,-3)>=8000000,8000000,ROUNDDOWN(Z12*$AF$3,-3))),"") -> 1221000
C13: システム等導入費 | P13: =IF(システム!AY21=0,"",システム!AY21) | Z13: =IF(システム!AS21=0,"",システム!AS21) | AJ13: =IFERROR(IF(Z13="","",IF(ROUNDDOWN(Z13*$AF$3,-3)>=8000000,8000000,ROUNDDOWN(Z13*$AF$3,-3))),"")
C14: 専門家指導費 | P14: =IF(専門!AY15=0,"",専門!AY15) -> 1650000 | Z14: =IF(専門!AS15=0,"",専門!AS15) -> 1500000 | AJ14: =IFERROR(IF(Z14="","",IF(ROUNDDOWN(Z14*$AF$3,-3)>=8000000,8000000,ROUNDDOWN(Z14*$AF$3,-3))),"") -> 1000000
C15: 不動産賃借料 | P15: =IF(賃借!AY15=0,"",賃借!AY15) -> 4197600 | Z15: =IF(賃借!AS15=0,"",賃借!AS15) -> 3816000 | AJ15: =IFERROR(IF(Z15="","",IF(ROUNDDOWN(Z15*$AF$3,-3)>=8000000,8000000,ROUNDDOWN(Z15*$AF$3,-3))),"") -> 2544000
C16: 販売促進費 | P16: =IF(販売!AY20=0,"",販売!AY20) -> 352000 | Z16: =IF(販売!AS20=0,"",販売!AS20) -> 320000 | AJ16: =IFERROR(IF(Z16="","",IF(ROUNDDOWN(Z16*$AF$3,-3)>=2000000,2000000,ROUNDDOWN(Z16*$AF$3,-3))),"") -> 213000
C17: その他経費 | P17: =IF(他!AY20=0,"",他!AY20) | Z17: =IF(他!AS20=0,"",他!AS20) | AJ17: =IFERROR(IF(Z17="","",IF(ROUNDDOWN(Z17*$AF$3,-3)>=1000000,1000000,ROUNDDOWN(Z17*$AF$3,-3))),"")
C18: 助成対象外経費
C19: 合 計 | P19: =SUM(P7:Y18) -> 11571763 | Z19: =SUM(Z7:AI17) -> 10519785 | AJ19: =IF(SUM(AJ7:AS17)<=8000000,SUM(AJ7:AS17),8000000) -> 7011000
A22: （２）資金調達内訳 | AM22: （単位：円）
A23: 区 分 | M23: 資 金 調 達 金 額 | X23: 調達先（名称等） | AK23: 進捗状況等
A24: 内 訳 | C24: 自 己 資 金 | AK24: (選択)
C25: 銀 行 借 入 金 | M25: 15000000 | X25: 城南信用金庫 | AK25: 折衝中
C26: 役 員 借 入 金 | M26: 2000000 | X26: 木下大輔 | AK26: 調達済
C27: その他 | AK27: (選択)
AK28: (選択)
C29: 合 計 | M29: =SUM(M24:W28) -> 17000000
B31: 注１ | E31: 「助成事業に要する経費」には、当助成事業を遂行するために必要な経費を記入してください。
E33: 「助成対象経費」には、「助成事業に要する経費」から消費税、振込手数料、通信費、光熱費等の間接経費を除いたものを記入してください。
B34: 注２
E36: 「助成金交付申請額」とは、「助成対象経費」のうち、助成金の交付を希望する額で「助成対象経費」に助成率を乗じた金額（千円未満切り捨て）で、かつ助成限度額以内となります。
B37: 注３
E39: 「助成事業に要する経費」と「資金調達金額」の合計が一致するように記入してください。
B40: 注４
